Workbook

Sheet OBLIGATORIOS
A2: NOMBRE | B2: NIVEL | C2: PISO | D2: HONGO ARZON | E2: ANILLO | F2: SALTO | G2: PARALELA | H2: FIJA | I2: Objetivo AA
A3: BRUNO BAEZ | B3: 4 | C3: 9 | D3: 9.6 | E3: 9.6 | F3: 9.9 | G3: 9.3 | H3: 9.3 | I3: =SUM(C3:H3)-6 -> 50.7
A4: MAURO REGAND | B4: 4 | C4: 9 | D4: 9.6 | E4: 9.9 | F4: 9.9 | G4: 9 | H4: 9.6 | I4: =SUM(C4:H4)-6 -> 51
A5: ALFREDO | B5: 4 | C5: 9.3 | D5: 9.9 | E5: 9.6 | F5: 9.9 | G5: 9 | H5: 9.3 | I5: =SUM(C5:H5)-6 -> 51
A6: ELIEL | B6: 4 | C6: 9 | D6: 9.6 | E6: 9.6 | F6: 9.9 | G6: 9.6 | H6: 9.6 | I6: =SUM(C6:H6)-6 -> 51.3
A7: JOSE MARIA | B7: 4 | C7: 9.6 | D7: 9.3 | E7: 9.6 | F7: 9.9 | G7: 9.3 | H7: 9.6 | I7: =SUM(C7:H7)-6 -> 51.3
A8: CARLOS AZNAR | B8: 4 | C8: 9 | D8: 9.6 | E8: 9.6 | F8: 9.9 | G8: 9.6 | H8: 9.6 | I8: =SUM(C8:H8)-6 -> 51.3
A9: DAVID | B9: 4 | C9: 9.3 | D9: 9.3 | E9: 9.6 | F9: 9.9 | G9: 9.3 | H9: 9.9 | I9: =SUM(C9:H9)-6 -> 51.3
A10: EMI | B10: 4 | C10: 9.6 | D10: 9.6 | E10: 9.9 | F10: 9.9 | G10: 9 | H10: 9.6 | I10: =SUM(C10:H10)-6 -> 51.6
A11: DIEGO CUEVAS | B11: 4 | C11: 9.3 | D11: 9.6 | E11: 9.9 | F11: 9.9 | G11: 9.3 | H11: 9.6 | I11: =SUM(C11:H11)-6 -> 51.6
A12: DIEGO CHAVEZ | B12: 4 | C12: 9.6 | D12: 9.6 | E12: 9.6 | F12: 9.9 | G12: 9.6 | H12: 9.6 | I12: =SUM(C12:H12)-6 -> 51.9
A13: NICO FLORES | B13: 4 | C13: 9.3 | D13: 9.6 | E13: 9.9 | F13: 9.9 | G13: 9.6 | H13: 9.6 | I13: =SUM(C13:H13)-6 -> 51.9
A14: SANTI CAMACHO | B14: 4 | C14: 9.6 | D14: 9.6 | E14: 9.9 | F14: 9.9 | G14: 9.6 | H14: 9.6 | I14: =SUM(C14:H14)-6 -> 52.2
... A22: SANTIAGO SIGLER | B22: 6 | C22: 9.3 | D22: 9.6 | E22: 9.3 | F22: 9.6 | G22: 9.3 | H22: 9 | I22: =SUM(C22:H22)-6 -> 50.1
A24: Rutina con 3 bonificaciones | B24: 9.9
A25: Rutina con 2 bonificaciones | B25: 9.6
A26: Rutina con 1 bonificacion | B26: 9.3
A27: Rutina sin bonificaciones | B27: 9

Sheet YERIK
A1: YERIK | C1: N 7 | D1: AA NP | E1: =G3+G14+G25+F37+G40+G51 -> 73.2 | F1: AA | G1: =G5+G16+G27+G37+G42+G53 -> 67.2 | H1: =(H4+H5+H6+H7+H8+H9+H10+H11+H16+H17+H18+H19+H20+H21+H22+H15+H27+H28+H29+H30+H31+H32+H33+H26+H41+H37+H44+H45+H46+H47+H48+H52+H42+H43+H55+H56+H57+H58+H59+H53+H54)/36 -> 0.70972222
A2: PISO | C2: =A1 -> YERIK | F2: NOTA D | G2: NP | H2: ETAPA DE ELEMENTO
A3: NOMBRE | B3: NÚM DE ID | C3: GRUPO | D3: VALOR | E3: Valor decimal | F3: =SUM(E4:E12) -> 0.8 | G3: =10+F3+F5+F11 -> 12.3
A4: Redondilla | B4: EV | C4: X | D4: A | E4: =IF(D4="F",0.6,IF(D4="C",0.3,IF(D4="D",0.4,IF(D4="E",0.5,IF(D4="A",0.1,IF(D4="G",0.7,IF(D4="H",0.8,IF(D4="B",0.2,"")))))))) -> 0.1 | F4: GRUPOS | G4: Probable NF | H4: 0.95
A5: Giro atrás | B5: 9 | C5: 4 | D5: B | E5: =IF(D5="F",0.6,IF(D5="C",0.3,IF(D5="D",0.4,IF(D5="E",0.5,IF(D5="A",0.1,IF(D5="G",0.7,IF(D5="H",0.8,IF(D5="B",0.2,"")))))))) -> 0.2 | F5: 1.5 | G5: =G3-1 -> 11.3 | H5: 0.6
A6: Arabesca | B6: 61 | C6: 1 | D6: A | E6: =IF(D6="F",0.6,IF(D6="C",0.3,IF(D6="D",0.4,IF(D6="E",0.5,IF(D6="A",0.1,IF(D6="G",0.7,IF(D6="H",0.8,IF(D6="B",0.2,"")))))))) -> 0.1 | H6: 0.7
A7: Resorte | B7: 1 | C7: 2 | D7: A | E7: =IF(D7="F",0.6,IF(D7="C",0.3,IF(D7="D",0.4,IF(D7="E",0.5,IF(D7="A",0.1,IF(D7="G",0.7,IF(D7="H",0.8,IF(D7="B",0.2,"")))))))) -> 0.1 | H7: 0.7
A8: Mortal agru ade | B8: 13 | C8: 2 | D8: A | E8: =IF(D8="F",0.6,IF(D8="C",0.3,IF(D8="D",0.4,IF(D8="E",0.5,IF(D8="A",0.1,IF(D8="G",0.7,IF(D8="H",0.8,IF(D8="B",0.2,"")))))))) -> 0.1 | H8: 0.85
A9: Sissone | H9: 0.9
A10: Redondilla | E10: =IF(D10="F",0.6,IF(D10="C",0.3,IF(D10="D",0.4,IF(D10="E",0.5,IF(D10="A",0.1,IF(D10="G",0.7,IF(D10="H",0.8,IF(D10="B",0.2,"")))))))) | F10: BPP | H10: 0.95
A11: Mortal Ext atrás | B11: 2 | C11: 3 | D11: B | E11: =IF(D11="F",0.6,IF(D11="C",0.3,IF(D11="D",0.4,IF(D11="E",0.5,IF(D11="A",0.1,IF(D11="G",0.7,IF(D11="H",0.8,IF(D11="B",0.2,"")))))))) -> 0.2 | H11: 0.8
A13: ARZONES | C13: =A1 -> YERIK | F13: NOTA D | G13: NP | H13: ETAPA DE ELEMENTO
A14: NOMBRE | B14: NÚM DE ID | C14: GRUPO | D14: VALOR | E14: Valor decimal | F14: =SUM(E15:E21)+F18 -> 0.5 | G14: =10+F14+F16+G23 -> 12
A15: Molino | B15: 7 | C15: 2 | D15: A | E15: =IF(D15="F",0.6,IF(D15="C",0.3,IF(D15="D",0.4,IF(D15="E",0.5,IF(D15="A",0.1,IF(D15="G",0.7,IF(D15="H",0.8,IF(D15="B",0.2,"")))))))) -> 0.1 | F15: GRUPOS | G15: Probable NF | H15: 0.8
A16: 1/4 Splindle | B16: 25 | C16: 2 | D16: A | E16: =IF(D16="F",0.6,IF(D16="C",0.3,IF(D16="D",0.4,IF(D16="E",0.5,IF(D16="A",0.1,IF(D16="G",0.7,IF(D16="H",0.8,IF(D16="B",0.2,"")))))))) -> 0.1 | F16: 1.5 | G16: =G14-1 -> 11 | H16: 0.65
A17: Tijera falsa | H17: 0.7
A18: Corte tijera | B18: 1 | C18: 1 | D18: A | E18: =IF(D18="F",0.6,IF(D18="C",0.3,IF(D18="D",0.4,IF(D18="E",0.5,IF(D18="A",0.1,IF(D18="G",0.7,IF(D18="H",0.8,IF(D18="B",0.2,"")))))))) -> 0.1 | H18: 0.65
A19: Molino en arzones | B19: 1 | C19: 2 | D19: A | E19: =IF(D19="F",0.6,IF(D19="C",0.3,IF(D19="D",0.4,IF(D19="E",0.5,IF(D19="A",0.1,IF(D19="G",0.7,IF(D19="H",0.8,IF(D19="B",0.2,"")))))))) -> 0.1 | H19: 0.2
A20: Bajada lateral | B20: 1 | C20: 3 | D20: A | E20: =IF(D20="F",0.6,IF(D20="C",0.3,IF(D20="D",0.4,IF(D20="E",0.5,IF(D20="A",0.1,IF(D20="G",0.7,IF(D20="H",0.8,IF(D20="B",0.2,"")))))))) -> 0.1 | H20: 0.2
A21: Molino | H21: 0.5
A22: Finlandesa | B22: 1 | C22: 4 | D22: A | E22: =IF(D22="F",0.6,IF(D22="C",0.3,IF(D22="D",0.4,IF(D22="E",0.5,IF(D22="A",0.1,IF(D22="G",0.7,IF(D22="H",0.8,IF(D22="B",0.2,"")))))))) -> 0.1 | H22: 0.7
A24: ANILLOS | C24: =A1 -> YERIK | F24: NOTA D | G24: NP | H24: ETAPA DE ELEMENTO
A25: NOMBRE | B25: NÚM DE ID | C25: GRUPO | D25: VALOR | E25: Valor decimal | F25: =SUM(E26:E33)+F29 -> 0.7 | G25: =10+F25+F27+F33 -> 12.2
A26: L sit colgado | B26: EV | C26: X | D26: A | E26: =IF(D26="F",0.6,IF(D26="C",0.3,IF(D26="D",0.4,IF(D26="E",0.5,IF(D26="A",0.1,IF(D26="G",0.7,IF(D26="H",0.8,IF(D26="B",0.2,"")))))))) -> 0.1 | F26: GRUPOS | G26: Probable NF | H26: 0.9
A27: Vela | B27: EV | C27: X | D27: A | E27: =IF(D27="F",0.6,IF(D27="C",0.3,IF(D27="D",0.4,IF(D27="E",0.5,IF(D27="A",0.1,IF(D27="G",0.7,IF(D27="H",0.8,IF(D27="B",0.2,"")))))))) -> 0.1 | F27: 1.5 | G27: =G25-1 -> 11.2 | H27: 0.9
A28: Sandwich | E28: =IF(D28="F",0.6,IF(D28="C",0.3,IF(D28="D",0.4,IF(D28="E",0.5,IF(D28="A",0.1,IF(D28="G",0.7,IF(D28="H",0.8,IF(D28="B",0.2,""))))))))
A29: Inglesa | B29: 31 | C29: 1 | D29: A | E29: =IF(D29="F",0.6,IF(D29="C",0.3,IF(D29="D",0.4,IF(D29="E",0.5,IF(D29="A",0.1,IF(D29="G",0.7,IF(D29="H",0.8,IF(D29="B",0.2,"")))))))) -> 0.1 | H29: 0.7
A30: L sit 2" | B30: 1 | C30: 2 | D30: A | E30: =IF(D30="F",0.6,IF(D30="C",0.3,IF(D30="D",0.4,IF(D30="E",0.5,IF(D30="A",0.1,IF(D30="G",0.7,IF(D30="H",0.8,IF(D30="B",0.2,"")))))))) -> 0.1 | H30: 0.9
A31: Parado de hombros | D31: =IF(C31="F",0.6,IF(C31="C",0.3,IF(C31="D",0.4,IF(C31="E",0.5,IF(C31="A",0.1,IF(C31="G",0.7,IF(C31="H",0.8,IF(C31="B",0.2,"")))))))) | E31: =IF(D31="F",0.6,IF(D31="C",0.3,IF(D31="D",0.4,IF(D31="E",0.5,IF(D31="A",0.1,IF(D31="G",0.7,IF(D31="H",0.8,IF(D31="B",0.2,"")))))))) | H31: 0.85
A32: Dislocada | B32: 25 | C32: 1 | D32: A | E32: =IF(D32="F",0.6,IF(D32="C",0.3,IF(D32="D",0.4,IF(D32="E",0.5,IF(D32="A",0.1,IF(D32="G",0.7,IF(D32="H",0.8,IF(D32="B",0.2,"")))))))) -> 0.1 | F32: BPP
A33: Doble atras en c | B33: 32 | C33: 4 | D33: B | E33: =IF(D33="F",0.6,IF(D33="C",0.3,IF(D33="D",0.4,IF(D33="E",0.5,IF(D33="A",0.1,IF(D33="G",0.7,IF(D33="H",0.8,IF(D33="B",0.2,"")))))))) -> 0.2 | H33: 0.6
A35: SALTO DE CABALLO | C35: =A1 -> YERIK | H35: ETAPA DE ELEMENTO
A36: NOMBRE | B36: NÚM DE ID | C36: GRUPO | D36: VALOR | E36: NOTA D | F36: SALTOS | G36: Probable NF
A37: Tsukahara en carpa | B37: 308 | C37: 3 | D37: 2.4 | F37: =10+D37 -> 12.4 | G37: =F37-1 -> 11.4 | H37: 0.6
A39: PARALELAS | C39: =A1 -> YERIK | F39: NOTA D | G39: NP | H39: ETAPA DE ELEMENTO
A40: NOMBRE | B40: NÚM DE ID | C40: GRUPO | D40: VALOR | E40: Valor decimal | F40: =SUM(E41:E48)+F44 -> 0.7 | G40: =10+F40+F42+F48 -> 12.2
A41: Alemana | B41: 73 | C41: 3 | D41: A | E41: =IF(D41="F",0.6,IF(D41="C",0.3,IF(D41="D",0.4,IF(D41="E",0.5,IF(D41="A",0.1,IF(D41="G",0.7,IF(D41="H",0.8,IF(D41="B",0.2,"")))))))) -> 0.1 | F41: GRUPOS | G41: Probable NF
A42: Vuelo | B42: 1 | C42: 2 | D42: A | E42: =IF(D42="F",0.6,IF(D42="C",0.3,IF(D42="D",0.4,IF(D42="E",0.5,IF(D42="A",0.1,IF(D42="G",0.7,IF(D42="H",0.8,IF(D42="B",0.2,"")))))))) -> 0.1 | F42: 1.5 | G42: =G40-1 -> 11.2
A43: Braq Subida de pecho | B43: 1 | C43: 1 | D43: A | E43: =IF(D43="F",0.6,IF(D43="C",0.3,IF(D43="D",0.4,IF(D43="E",0.5,IF(D43="A",0.1,IF(D43="G",0.7,IF(D43="H",0.8,IF(D43="B",0.2,"")))))))) -> 0.1 | H43: 0.75
A44: L-sit | B44: 7 | C44: 2 | D44: A | E44: =IF(D44="F",0.6,IF(D44="C",0.3,IF(D44="D",0.4,IF(D44="E",0.5,IF(D44="A",0.1,IF(D44="G",0.7,IF(D44="H",0.8,IF(D44="B",0.2,"")))))))) -> 0.1 | H44: 0.75
...

Sheet FER
A1: FER | C1: N 7 | D1: AA NP | E1: =G3+G14+G25+F37+G40+G51 -> 73.8 | F1: AA | G1: =G5+G16+G27+G37+G42+G53 -> 67.8 | H1: =(H4+H5+H6+H7+H8+H9+H10+H11+H16+H17+H18+H19+H20+H21+H22+H15+H27+H28+H29+H30+H31+H32+H33+H26+H41+H37+H44+H45+H46+H47+H48+H52+H42+H43+H55+H56+H57+H58+H59+H53+H54)/39 -> 0.76410256
A2: PISO | C2: =A1 -> FER | F2: NOTA D | G2: NP | H2: ETAPA DE ELEMENTO
A3: NOMBRE | B3: NÚM DE ID | C3: GRUPO | D3: VALOR | E3: Valor decimal | F3: =SUM(E4:E12) -> 0.9 | G3: =10+F3+F5+F11 -> 12.4
A4: Redondilla | B4: EV | C4: X | D4: A | E4: =IF(D4="F",0.6,IF(D4="C",0.3,IF(D4="D",0.4,IF(D4="E",0.5,IF(D4="A",0.1,IF(D4="G",0.7,IF(D4="H",0.8,IF(D4="B",0.2,"")))))))) -> 0.1 | F4: GRUPOS | G4: Probable NF | H4: 0.95
A5: Giro atrás | B5: 9 | C5: 4 | D5: B | E5: =IF(D5="F",0.6,IF(D5="C",0.3,IF(D5="D",0.4,IF(D5="E",0.5,IF(D5="A",0.1,IF(D5="G",0.7,IF(D5="H",0.8,IF(D5="B",0.2,"")))))))) -> 0.2 | F5: 1.5 | G5: =G3-1 -> 11.4 | H5: 0.5
A6: Mortal Ext ade | B6: 14 | C6: 2 | D6: B | E6: =IF(D6="F",0.6,IF(D6="C",0.3,IF(D6="D",0.4,IF(D6="E",0.5,IF(D6="A",0.1,IF(D6="G",0.7,IF(D6="H",0.8,IF(D6="B",0.2,"")))))))) -> 0.2 | H6: 0.6
A7: Sissone | H7: 0.2
A8: Mortal agru ade | B8: 13 | C8: 2 | D8: A | E8: =IF(D8="F",0.6,IF(D8="C",0.3,IF(D8="D",0.4,IF(D8="E",0.5,IF(D8="A",0.1,IF(D8="G",0.7,IF(D8="H",0.8,IF(D8="B",0.2,"")))))))) -> 0.1 | H8: 0.9
A9: Arabesca | B9: 61 | C9: 1 | D9: A | E9: =IF(D9="F",0.6,IF(D9="C",0.3,IF(D9="D",0.4,IF(D9="E",0.5,IF(D9="A",0.1,IF(D9="G",0.7,IF(D9="H",0.8,IF(D9="B",0.2,"")))))))) -> 0.1 | H9: 0.9
A10: Redondilla | E10: =IF(D10="F",0.6,IF(D10="C",0.3,IF(D10="D",0.4,IF(D10="E",0.5,IF(D10="A",0.1,IF(D10="G",0.7,IF(D10="H",0.8,IF(D10="B",0.2,"")))))))) | F10: BPP | H10: 0.95
A11: Mortal Ext atrás | B11: 2 | C11: 3 | D11: B | E11: =IF(D11="F",0.6,IF(D11="C",0.3,IF(D11="D",0.4,IF(D11="E",0.5,IF(D11="A",0.1,IF(D11="G",0.7,IF(D11="H",0.8,IF(D11="B",0.2,"")))))))) -> 0.2 | H11: 0.9
A13: ARZONES | C13: =A1 -> FER | F13: NOTA D | G13: NP | H13: ETAPA DE ELEMENTO
A14: NOMBRE | B14: NÚM DE ID | C14: GRUPO | D14: VALOR | E14: Valor decimal | F14: =SUM(E15:E23)+F18 -> 0.9 | G14: =10+F14+F16+G23 -> 12.4
A15: Corte tijera | B15: 1 | C15: 1 | D15: A | E15: =IF(D15="F",0.6,IF(D15="C",0.3,IF(D15="D",0.4,IF(D15="E",0.5,IF(D15="A",0.1,IF(D15="G",0.7,IF(D15="H",0.8,IF(D15="B",0.2,"")))))))) -> 0.1 | F15: GRUPOS | G15: Probable NF | H15: 0.85
A16: Molino en arzones | E16: =IF(D16="F",0.6,IF(D16="C",0.3,IF(D16="D",0.4,IF(D16="E",0.5,IF(D16="A",0.1,IF(D16="G",0.7,IF(D16="H",0.8,IF(D16="B",0.2,"")))))))) | F16: 1.5 | G16: =G14-1 -> 11.4 | H16: 0.7
A17: Cheka | B17: 74 | C17: 2 | D17: B | E17: =IF(D17="F",0.6,IF(D17="C",0.3,IF(D17="D",0.4,IF(D17="E",0.5,IF(D17="A",0.1,IF(D17="G",0.7,IF(D17="H",0.8,IF(D17="B",0.2,"")))))))) -> 0.2 | H17: 0.75
A18: Bajada lateral | B18: 8 | C18: 3 | D18: B | E18: =IF(D18="F",0.6,IF(D18="C",0.3,IF(D18="D",0.4,IF(D18="E",0.5,IF(D18="A",0.1,IF(D18="G",0.7,IF(D18="H",0.8,IF(D18="B",0.2,"")))))))) -> 0.2 | H18: 0.7
A19: Molino | E19: =IF(D19="F",0.6,IF(D19="C",0.3,IF(D19="D",0.4,IF(D19="E",0.5,IF(D19="A",0.1,IF(D19="G",0.7,IF(D19="H",0.8,IF(D19="B",0.2,"")))))))) | H19: 0.7
A20: 1/4 de kher | B20: 25 | C20: 2 | D20: A | E20: =IF(D20="F",0.6,IF(D20="C",0.3,IF(D20="D",0.4,IF(D20="E",0.5,IF(D20="A",0.1,IF(D20="G",0.7,IF(D20="H",0.8,IF(D20="B",0.2,"")))))))) -> 0.1 | H20: 0.75
A21: 1/2 splindle | B21: 25 | C21: 2 | D21: B | E21: =IF(D21="F",0.6,IF(D21="C",0.3,IF(D21="D",0.4,IF(D21="E",0.5,IF(D21="A",0.1,IF(D21="G",0.7,IF(D21="H",0.8,IF(D21="B",0.2,"")))))))) -> 0.2 | H21: 0.75
A22: Finlandesa | B22: 1 | C22: 4 | D22: A | E22: =IF(D22="F",0.6,IF(D22="C",0.3,IF(D22="D",0.4,IF(D22="E",0.5,IF(D22="A",0.1,IF(D22="G",0.7,IF(D22="H",0.8,IF(D22="B",0.2,"")))))))) -> 0.1 | H22: 0.8
A24: ANILLOS | C24: =A1 -> FER | F24: NOTA D | G24: NP | H24: ETAPA DE ELEMENTO
A25: NOMBRE | B25: NÚM DE ID | C25: GRUPO | D25: VALOR | E25: Valor decimal | F25: =SUM(E26:E33)+F29 -> 0.7 | G25: =10+F25+F27+F33 -> 12.2
A26: L sit colgado | B26: EV | C26: X | D26: A | E26: =IF(D26="F",0.6,IF(D26="C",0.3,IF(D26="D",0.4,IF(D26="E",0.5,IF(D26="A",0.1,IF(D26="G",0.7,IF(D26="H",0.8,IF(D26="B",0.2,"")))))))) -> 0.1 | F26: GRUPOS | G26: Probable NF | H26: 0.9
A27: Vela | B27: EV | C27: X | D27: A | E27: =IF(D27="F",0.6,IF(D27="C",0.3,IF(D27="D",0.4,IF(D27="E",0.5,IF(D27="A",0.1,IF(D27="G",0.7,IF(D27="H",0.8,IF(D27="B",0.2,"")))))))) -> 0.1 | F27: 1.5 | G27: =G25-1 -> 11.2 | H27: 0.9
A28: Sandwich | E28: =IF(D28="F",0.6,IF(D28="C",0.3,IF(D28="D",0.4,IF(D28="E",0.5,IF(D28="A",0.1,IF(D28="G",0.7,IF(D28="H",0.8,IF(D28="B",0.2,""))))))))
A29: Inglesa | B29: 31 | C29: 1 | D29: A | E29: =IF(D29="F",0.6,IF(D29="C",0.3,IF(D29="D",0.4,IF(D29="E",0.5,IF(D29="A",0.1,IF(D29="G",0.7,IF(D29="H",0.8,IF(D29="B",0.2,"")))))))) -> 0.1 | H29: 0.7
A30: L sit 2" | B30: 1 | C30: 2 | D30: A | E30: =IF(D30="F",0.6,IF(D30="C",0.3,IF(D30="D",0.4,IF(D30="E",0.5,IF(D30="A",0.1,IF(D30="G",0.7,IF(D30="H",0.8,IF(D30="B",0.2,"")))))))) -> 0.1 | H30: 0.9
A31: Parado de hombros | B31: EV | C31: X | D31: A | E31: =IF(D31="F",0.6,IF(D31="C",0.3,IF(D31="D",0.4,IF(D31="E",0.5,IF(D31="A",0.1,IF(D31="G",0.7,IF(D31="H",0.8,IF(D31="B",0.2,"")))))))) -> 0.1 | H31: 0.7
A32: Mantencion a impulso | E32: =IF(D32="F",0.6,IF(D32="C",0.3,IF(D32="D",0.4,IF(D32="E",0.5,IF(D32="A",0.1,IF(D32="G",0.7,IF(D32="H",0.8,IF(D32="B",0.2,"")))))))) | F32: BPP
A33: Doble atras en c | B33: 32 | C33: 4 | D33: B | E33: =IF(D33="F",0.6,IF(D33="C",0.3,IF(D33="D",0.4,IF(D33="E",0.5,IF(D33="A",0.1,IF(D33="G",0.7,IF(D33="H",0.8,IF(D33="B",0.2,"")))))))) -> 0.2 | H33: 0.8
A35: SALTO DE CABALLO | C35: =A1 -> FER | H35: ETAPA DE ELEMENTO
A36: NOMBRE | B36: NÚM DE ID | C36: GRUPO | D36: VALOR | E36: NOTA D | F36: SALTOS | G36: Probable NF
A37: Tsukahara en C | B37: 307 | C37: 3 | D37: 2.2 | F37: =10+D37 -> 12.2 | G37: =F37-1 -> 11.2 | H37: 0.6
A39: PARALELAS | C39: =A1 -> FER | F39: NOTA D | G39: NP | H39: ETAPA DE ELEMENTO
A40: NOMBRE | B40: NÚM DE ID | C40: GRUPO | D40: VALOR | E40: Valor decimal | F40: =SUM(E41:E48)+F44 -> 0.9 | G40: =10+F40+F42+F48 -> 12.4
A41: Alemana | B41: 73 | C41: 3 | D41: A | E41: =IF(D41="F",0.6,IF(D41="C",0.3,IF(D41="D",0.4,IF(D41="E",0.5,IF(D41="A",0.1,IF(D41="G",0.7,IF(D41="H",0.8,IF(D41="B",0.2,"")))))))) -> 0.1 | F41: GRUPOS | G41: Probable NF | H41: 0.8
A42: L-sit | B42: 7 | C42: 2 | D42: A | E42: =IF(D42="F",0.6,IF(D42="C",0.3,IF(D42="D",0.4,IF(D42="E",0.5,IF(D42="A",0.1,IF(D42="G",0.7,IF(D42="H",0.8,IF(D42="B",0.2,"")))))))) -> 0.1 | F42: 1.5 | G42: =G40-1 -> 11.4 | H42: 0.7
A43: Kato | B43: 8 | C43: 2 | D43: B | E43: =IF(D43="F",0.6,IF(D43="C",0.3,IF(D43="D",0.4,IF(D43="E",0.5,IF(D43="A",0.1,IF(D43="G",0.7,IF(D43="H",0.8,IF(D43="B",0.2,"")))))))) -> 0.2 | H43: 0.75
A44: Moy extendido | B44: 15 | C44: 3 | D44: C | E44: =IF(D44="F",0.6,IF(D44="C",0.3,IF(D44="D",0.4,IF(D44="E",0.5,IF(D44="A",0.1,IF(D44="G",0.7,IF(D44="H",0.8,IF(D44="B",0.2,"")))))))) -> 0.3 | H44: 0.75
...

Sheet VELA
A1: VELA | D1: N 8 | E1: AA NP | F1: =H3+H14+H25+F37+H40+H51 -> 77.2 | G1: AA | H1: =H5+H16+H27+G37+H42+H53 -> 68.4 | I1: =(I4+I5+I6+I7+I8+I9+I10+I11+I16+I17+I18+I19+I20+I21+I22+I15+I27+I28+I29+I30+I31+I32+I33+I26+I41+I37+I44+I45+I46+I47+I48+I52+I42+I43+I55+I56+I57+I58+I59+I53+I54)/41 -> 0.77073171
A2: PISO | E2: =A1 -> VELA | G2: NOTA D | H2: NP | I2: ETAPA DE ELEMENTO
A3: NOMBRE | B3: NÚM DE ID | C3: GRUPO | D3: VALOR | E3: Valor decimal | F3: REQUISITO | G3: =SUM(E5:E8) -> 0.8 | H3: =10+G3+G5+G11 -> 12.8
A4: Redondilla | B4: EV | C4: X | D4: A | E4: =IF(D4="F",0.6,IF(D4="C",0.3,IF(D4="D",0.4,IF(D4="E",0.5,IF(D4="A",0.1,IF(D4="G",0.7,IF(D4="H",0.8,IF(D4="B",0.2,"")))))))) -> 0.1 | G4: GRUPOS | H4: Probable NF | I4: 0.9
A5: Flick Flack | B5: 13 | C5: 3 | D5: A | E5: =IF(D5="F",0.6,IF(D5="C",0.3,IF(D5="D",0.4,IF(D5="E",0.5,IF(D5="A",0.1,IF(D5="G",0.7,IF(D5="H",0.8,IF(D5="B",0.2,"")))))))) -> 0.1 | F5: III | G5: 2 | H5: =H3-1.5 -> 11.3 | I5: 0.85
A6: Giro y medio atrás | B6: 9 | C6: 4 | D6: C | E6: =IF(D6="F",0.6,IF(D6="C",0.3,IF(D6="D",0.4,IF(D6="E",0.5,IF(D6="A",0.1,IF(D6="G",0.7,IF(D6="H",0.8,IF(D6="B",0.2,"")))))))) -> 0.3 | F6: IV | I6: 0.65
A7: Tempo | B7: 2 | C7: 3 | D7: B | E7: =IF(D7="F",0.6,IF(D7="C",0.3,IF(D7="D",0.4,IF(D7="E",0.5,IF(D7="A",0.1,IF(D7="G",0.7,IF(D7="H",0.8,IF(D7="B",0.2,"")))))))) -> 0.2 | F7: III | I7: 0.85
A8: Mortal Ext atrás | B8: 2 | C8: 3 | D8: B | E8: =IF(D8="F",0.6,IF(D8="C",0.3,IF(D8="D",0.4,IF(D8="E",0.5,IF(D8="A",0.1,IF(D8="G",0.7,IF(D8="H",0.8,IF(D8="B",0.2,"")))))))) -> 0.2 | F8: III | I8: 0.85
A9: Mortal Agru ade | B9: 13 | C9: 2 | D9: A | E9: =IF(D9="F",0.6,IF(D9="C",0.3,IF(D9="D",0.4,IF(D9="E",0.5,IF(D9="A",0.1,IF(D9="G",0.7,IF(D9="H",0.8,IF(D9="B",0.2,"")))))))) -> 0.1 | F9: II | I9: 0.75
A10: Arabesca | B10: 61 | C10: 1 | D10: A | E10: =IF(D10="F",0.6,IF(D10="C",0.3,IF(D10="D",0.4,IF(D10="E",0.5,IF(D10="A",0.1,IF(D10="G",0.7,IF(D10="H",0.8,IF(D10="B",0.2,"")))))))) -> 0.1 | F10: I | G10: BPS | I10: 0.85
A11: Giro atrás | B11: 9 | C11: 4 | D11: B | E11: =IF(D11="F",0.6,IF(D11="C",0.3,IF(D11="D",0.4,IF(D11="E",0.5,IF(D11="A",0.1,IF(D11="G",0.7,IF(D11="H",0.8,IF(D11="B",0.2,"")))))))) -> 0.2 | F11: IV | I11: 0.9
A13: ARZONES | E13: =A1 -> VELA | G13: NOTA D | H13: NP | I13: ETAPA DE ELEMENTO
A14: NOMBRE | B14: NÚM DE ID | C14: GRUPO | D14: VALOR | E14: Valor decimal | F14: REQUISITO | G14: =SUM(E15:E22) -> 1.4 | H14: =10+G14+G16+G22 -> 13
A15: Molino | B15: 7 | C15: 2 | D15: A | E15: =IF(D15="F",0.6,IF(D15="C",0.3,IF(D15="D",0.4,IF(D15="E",0.5,IF(D15="A",0.1,IF(D15="G",0.7,IF(D15="H",0.8,IF(D15="B",0.2,"")))))))) -> 0.1 | F15: II | G15: GRUPOS | H15: Probable NF | I15: 0.65
A16: 1/2 Magyar | B16: 32 | C16: 3 | D16: B | E16: =IF(D16="F",0.6,IF(D16="C",0.3,IF(D16="D",0.4,IF(D16="E",0.5,IF(D16="A",0.1,IF(D16="G",0.7,IF(D16="H",0.8,IF(D16="B",0.2,"")))))))) -> 0.2 | F16: III | G16: 1.6 | H16: =H14-1.5 -> 11.5 | I16: 0.85
A17: 1/2 Sivado | B17: 38 | C17: 3 | D17: B | E17: =IF(D17="F",0.6,IF(D17="C",0.3,IF(D17="D",0.4,IF(D17="E",0.5,IF(D17="A",0.1,IF(D17="G",0.7,IF(D17="H",0.8,IF(D17="B",0.2,"")))))))) -> 0.2 | F17: III | I17: 0.75
A18: Magyar | B18: 34 | C18: 3 | D18: D | E18: =IF(D18="F",0.6,IF(D18="C",0.3,IF(D18="D",0.4,IF(D18="E",0.5,IF(D18="A",0.1,IF(D18="G",0.7,IF(D18="H",0.8,IF(D18="B",0.2,"")))))))) -> 0.4 | F18: III | I18: 0.75
A19: Circulo frontal | B19: 13 | C19: 2 | D19: A | E19: =IF(D19="F",0.6,IF(D19="C",0.3,IF(D19="D",0.4,IF(D19="E",0.5,IF(D19="A",0.1,IF(D19="G",0.7,IF(D19="H",0.8,IF(D19="B",0.2,"")))))))) -> 0.1 | F19: II | I19: 0.85
A20: 1/2 Splindle | B20: 26 | C20: 2 | D20: B | E20: =IF(D20="F",0.6,IF(D20="C",0.3,IF(D20="D",0.4,IF(D20="E",0.5,IF(D20="A",0.1,IF(D20="G",0.7,IF(D20="H",0.8,IF(D20="B",0.2,"")))))))) -> 0.2 | F20: II | I20: 0.7
A21: Thomas | B21: EV | C21: 2 | D21: A | E21: =IF(D21="F",0.6,IF(D21="C",0.3,IF(D21="D",0.4,IF(D21="E",0.5,IF(D21="A",0.1,IF(D21="G",0.7,IF(D21="H",0.8,IF(D21="B",0.2,"")))))))) -> 0.1 | F21: I | G21: BPS | I21: 0.8
A22: Finlandesa | B22: 9 | C22: 4 | D22: A | E22: =IF(D22="F",0.6,IF(D22="C",0.3,IF(D22="D",0.4,IF(D22="E",0.5,IF(D22="A",0.1,IF(D22="G",0.7,IF(D22="H",0.8,IF(D22="B",0.2,"")))))))) -> 0.1 | F22: IV | I22: 0.65
A24: ANILLOS | E24: =A1 -> VELA | G24: NOTA D | H24: NP | I24: ETAPA DE ELEMENTO
A25: NOMBRE | B25: NÚM DE ID | C25: GRUPO | D25: VALOR | E25: Valor decimal | F25: REQUISITO | G25: =SUM(E26:E33) -> 1.4 | H25: =10+G25+G27+G33 -> 13.1
A26: L sit colgado | B26: EV | C26: X | D26: A | E26: =IF(D26="F",0.6,IF(D26="C",0.3,IF(D26="D",0.4,IF(D26="E",0.5,IF(D26="A",0.1,IF(D26="G",0.7,IF(D26="H",0.8,IF(D26="B",0.2,"")))))))) -> 0.1 | F26: EV | G26: GRUPOS | H26: Probable NF | I26: 0.9
A27: Vela | B27: EV | C27: X | D27: A | E27: =IF(D27="F",0.6,IF(D27="C",0.3,IF(D27="D",0.4,IF(D27="E",0.5,IF(D27="A",0.1,IF(D27="G",0.7,IF(D27="H",0.8,IF(D27="B",0.2,"")))))))) -> 0.1 | F27: EV | G27: 1.7 | H27: =H25-1.5 -> 11.6 | I27: 0.95
A28: Inglesa | B28: 31 | C28: 1 | D28: A | E28: =IF(D28="F",0.6,IF(D28="C",0.3,IF(D28="D",0.4,IF(D28="E",0.5,IF(D28="A",0.1,IF(D28="G",0.7,IF(D28="H",0.8,IF(D28="B",0.2,"")))))))) -> 0.1 | F28: I | I28: 0.5
A29: L sit | B29: 1 | C29: 2 | D29: A | E29: =IF(D29="F",0.6,IF(D29="C",0.3,IF(D29="D",0.4,IF(D29="E",0.5,IF(D29="A",0.1,IF(D29="G",0.7,IF(D29="H",0.8,IF(D29="B",0.2,"")))))))) -> 0.1 | F29: II | I29: 0.9
A30: Kato 3" | B30: 26 | C30: 2 | D30: B | E30: =IF(D30="F",0.6,IF(D30="C",0.3,IF(D30="D",0.4,IF(D30="E",0.5,IF(D30="A",0.1,IF(D30="G",0.7,IF(D30="H",0.8,IF(D30="B",0.2,"")))))))) -> 0.2 | F30: III | I30: 0.85
A31: Gigante 3" | B31: 75 | C31: 1 | D31: C | E31: =IF(D31="F",0.6,IF(D31="C",0.3,IF(D31="D",0.4,IF(D31="E",0.5,IF(D31="A",0.1,IF(D31="G",0.7,IF(D31="H",0.8,IF(D31="B",0.2,"")))))))) -> 0.3 | F31: I | I31: 0.75
A32: Molino 3" | B32: 62 | C32: 1 | D32: C | E32: =IF(D32="F",0.6,IF(D32="C",0.3,IF(D32="D",0.4,IF(D32="E",0.5,IF(D32="A",0.1,IF(D32="G",0.7,IF(D32="H",0.8,IF(D32="B",0.2,"")))))))) -> 0.3 | F32: I | G32: BPS | I32: 0.85
A33: Doble atras en c | B33: 32 | C33: 4 | D33: B | E33: =IF(D33="F",0.6,IF(D33="C",0.3,IF(D33="D",0.4,IF(D33="E",0.5,IF(D33="A",0.1,IF(D33="G",0.7,IF(D33="H",0.8,IF(D33="B",0.2,"")))))))) -> 0.2 | F33: IV | I33: 0.5
A35: SALTO DE CABALLO | C35: =A1 -> VELA | I35: ETAPA DE ELEMENTO
A36: NOMBRE | B36: NÚM DE ID | C36: GRUPO | D36: VALOR | E36: NOTA D | F36: SALTOS | G36: Probable NF
A37: Tsukahara en carpa | B37: 308 | C37: 3 | D37: 2.4 | F37: =10+D37 -> 12.4 | G37: =F37-1.3 -> 11.1 | I37: 0.2
A39: PARALELAS | E39: =A1 -> VELA | G39: NOTA D | H39: NP | I39: ETAPA DE ELEMENTO
A40: NOMBRE | B40: NÚM DE ID | C40: GRUPO | D40: VALOR | E40: Valor decimal | F40: REQUISITO | G40: =SUM(E41:E48) -> 1.4 | H40: =10+G40+G42+G48 -> 13
A41: Alemana | B41: 73 | C41: 3 | D41: A | E41: =IF(D41="F",0.6,IF(D41="C",0.3,IF(D41="D",0.4,IF(D41="E",0.5,IF(D41="A",0.1,IF(D41="G",0.7,IF(D41="H",0.8,IF(D41="B",0.2,"")))))))) -> 0.1 | F41: III | G41: GRUPOS | H41: Probable NF | I41: 0.85
A42: Vuelo | B42: 1 | C42: 2 | D42: A | E42: =IF(D42="F",0.6,IF(D42="C",0.3,IF(D42="D",0.4,IF(D42="E",0.5,IF(D42="A",0.1,IF(D42="G",0.7,IF(D42="H",0.8,IF(D42="B",0.2,"")))))))) -> 0.1 | F42: I | G42: 1.6 | H42: =H40-1.5 -> 11.5 | I42: 0.85
A43: Kenmotsu | B43: 21 | C43: 3 | D43: C | E43: =IF(D43="F",0.6,IF(D43="C",0.3,IF(D43="D",0.4,IF(D43="E",0.5,IF(D43="A",0.1,IF(D43="G",0.7,IF(D43="H",0.8,IF(D43="B",0.2,"")))))))) -> 0.3 | F43: III | I43: 0.85
A44: Moy extendido | B44: 15 | C44: 3 | D44: C | E44: =IF(D44="F",0.6,IF(D44="C",0.3,IF(D44="D",0.4,IF(D44="E",0.5,IF(D44="A",0.1,IF(D44="G",0.7,IF(D44="H",0.8,IF(D44="B",0.2,"")))))))) -> 0.3 | F44: III | I44: 0.65
...

Sheet ISAAC
A1: ISAAC | C1: N 9 | D1: AA NP | E1: =G3+G15+G26+F38+G41+G52 -> 73.8 | F1: AA | G1: =G5+G17+G28+G38+G43+G54 -> 65 | H1: =(H4+H5+H6+H7+H8+H9+H10+H11+H17+H18+H19+H20+H21+H22+H23+H16+H28+H29+H30+H31+H32+H33+H34+H27+H42+H38+H45+H46+H47+H48+H49+H53+H43+H44+H56+H57+H58+H59+H60+H54+H55)/41 -> 0.67073171
A2: PISO | E2: =A1 -> ISAAC | F2: NOTA D | G2: NP | H2: ETAPA DE ELEMENTO
A3: NOMBRE | B3: NÚM DE ID | C3: GRUPO | D3: VALOR | E3: Valor decimal | F3: =SUM(E4:E12) -> 0.8 | G3: =10+F3+F5+F11 -> 12.2
A4: Resorte | B4: 1 | C4: 2 | D4: A | E4: =IF(D4="F",0.6,IF(D4="C",0.3,IF(D4="D",0.4,IF(D4="E",0.5,IF(D4="A",0.1,IF(D4="G",0.7,IF(D4="H",0.8,IF(D4="B",0.2,"")))))))) -> 0.1 | F4: GRUPOS | G4: Probable NF | H4: 0.1
A5: Mortal Ext ade | B5: 14 | C5: 2 | D5: B | E5: =IF(D5="F",0.6,IF(D5="C",0.3,IF(D5="D",0.4,IF(D5="E",0.5,IF(D5="A",0.1,IF(D5="G",0.7,IF(D5="H",0.8,IF(D5="B",0.2,"")))))))) -> 0.2 | F5: 1.4 | G5: =G3-1.5 -> 10.7 | H5: 0.5
A6: Giro atrás | B6: 9 | C6: 4 | D6: B | E6: =IF(D6="F",0.6,IF(D6="C",0.3,IF(D6="D",0.4,IF(D6="E",0.5,IF(D6="A",0.1,IF(D6="G",0.7,IF(D6="H",0.8,IF(D6="B",0.2,"")))))))) -> 0.2 | H6: 0.7
A7: Circulo en suelo | B7: 79 | C7: 1 | D7: A | E7: =IF(D7="F",0.6,IF(D7="C",0.3,IF(D7="D",0.4,IF(D7="E",0.5,IF(D7="A",0.1,IF(D7="G",0.7,IF(D7="H",0.8,IF(D7="B",0.2,"")))))))) -> 0.1 | H7: 0.6
A8: Arabesca | B8: 61 | C8: 1 | D8: A | E8: =IF(D8="F",0.6,IF(D8="C",0.3,IF(D8="D",0.4,IF(D8="E",0.5,IF(D8="A",0.1,IF(D8="G",0.7,IF(D8="H",0.8,IF(D8="B",0.2,"")))))))) -> 0.1 | H8: 0.85
A9: Mortal Carp ade | B9: 13 | C9: 2 | D9: A | E9: =IF(D9="F",0.6,IF(D9="C",0.3,IF(D9="D",0.4,IF(D9="E",0.5,IF(D9="A",0.1,IF(D9="G",0.7,IF(D9="H",0.8,IF(D9="B",0.2,"")))))))) -> 0.1 | H9: 0.85
A10: Flick Flack | B10: 13 | C10: 3 | D10: A | E10: =IF(D10="F",0.6,IF(D10="C",0.3,IF(D10="D",0.4,IF(D10="E",0.5,IF(D10="A",0.1,IF(D10="G",0.7,IF(D10="H",0.8,IF(D10="B",0.2,"")))))))) -> 0.1 | F10: BPS | H10: 0.9
A11: Mortal Ext atrás | B11: 2 | C11: 3 | D11: B | E11: =IF(D11="F",0.6,IF(D11="C",0.3,IF(D11="D",0.4,IF(D11="E",0.5,IF(D11="A",0.1,IF(D11="G",0.7,IF(D11="H",0.8,IF(D11="B",0.2,"")))))))) -> 0.2 | H11: 0.9
E12: -0.3 | F12: No doble
A14: ARZONES | E14: =A1 -> ISAAC | F14: NOTA D | G14: NP | H14: ETAPA DE ELEMENTO
A15: NOMBRE | B15: NÚM DE ID | C15: GRUPO | D15: VALOR | E15: Valor decimal | F15: =SUM(E16:E21) -> 0.6 | G15: =10+F15+F17+F23 -> 11.8
A16: Corte tijera | B16: 1 | C16: 1 | D16: A | E16: =IF(D16="F",0.6,IF(D16="C",0.3,IF(D16="D",0.4,IF(D16="E",0.5,IF(D16="A",0.1,IF(D16="G",0.7,IF(D16="H",0.8,IF(D16="B",0.2,"")))))))) -> 0.1 | F16: GRUPOS | G16: Probable NF | H16: 0.2
A17: Molino en arzones | B17: 1 | C17: 2 | D17: A | E17: =IF(D17="F",0.6,IF(D17="C",0.3,IF(D17="D",0.4,IF(D17="E",0.5,IF(D17="A",0.1,IF(D17="G",0.7,IF(D17="H",0.8,IF(D17="B",0.2,"")))))))) -> 0.1 | F17: 1.2 | G17: =G15-1.5 -> 10.3 | H17: 0.4
A18: Bajada lateral | B18: 1 | C18: 3 | D18: A | E18: =IF(D18="F",0.6,IF(D18="C",0.3,IF(D18="D",0.4,IF(D18="E",0.5,IF(D18="A",0.1,IF(D18="G",0.7,IF(D18="H",0.8,IF(D18="B",0.2,"")))))))) -> 0.1 | H18: 0.25
A19: Molino | B19: 7 | C19: 2 | D19: A | E19: =IF(D19="F",0.6,IF(D19="C",0.3,IF(D19="D",0.4,IF(D19="E",0.5,IF(D19="A",0.1,IF(D19="G",0.7,IF(D19="H",0.8,IF(D19="B",0.2,"")))))))) -> 0.1 | H19: 0.1
A20: 1/4 Splindle | B20: 25 | C20: 2 | D20: A | E20: =IF(D20="F",0.6,IF(D20="C",0.3,IF(D20="D",0.4,IF(D20="E",0.5,IF(D20="A",0.1,IF(D20="G",0.7,IF(D20="H",0.8,IF(D20="B",0.2,"")))))))) -> 0.1 | H20: 0.85
A21: Finlandesa | B21: 1 | C21: 4 | D21: A | E21: =IF(D21="F",0.6,IF(D21="C",0.3,IF(D21="D",0.4,IF(D21="E",0.5,IF(D21="A",0.1,IF(D21="G",0.7,IF(D21="H",0.8,IF(D21="B",0.2,"")))))))) -> 0.1 | H21: 0.05
F22: BPS | H22: 0.7
H23: 0.9
A25: ANILLOS | E25: =A1 -> ISAAC | F25: NOTA D | G25: NP | H25: ETAPA DE ELEMENTO
A26: NOMBRE | B26: NÚM DE ID | C26: GRUPO | D26: VALOR | E26: Valor decimal | F26: =SUM(E27:E34) -> 1.5 | G26: =10+F26+F28+F34 -> 12.8
A27: Inglesa a pajaro | B27: 68 | C27: 3 | D27: B | E27: =IF(D27="F",0.6,IF(D27="C",0.3,IF(D27="D",0.4,IF(D27="E",0.5,IF(D27="A",0.1,IF(D27="G",0.7,IF(D27="H",0.8,IF(D27="B",0.2,"")))))))) -> 0.2 | F27: GRUPOS | G27: Probable NF | H27: 0.5
A28: Cristo | B28: 68 | C28: 2 | D28: C | E28: =IF(D28="F",0.6,IF(D28="C",0.3,IF(D28="D",0.4,IF(D28="E",0.5,IF(D28="A",0.1,IF(D28="G",0.7,IF(D28="H",0.8,IF(D28="B",0.2,"")))))))) -> 0.3 | F28: 1.3 | G28: =G26-1.5 -> 11.3 | H28: 0.9
A29: Plancha dorsal | B29: 7 | C29: 2 | D29: A | E29: =IF(D29="F",0.6,IF(D29="C",0.3,IF(D29="D",0.4,IF(D29="E",0.5,IF(D29="A",0.1,IF(D29="G",0.7,IF(D29="H",0.8,IF(D29="B",0.2,"")))))))) -> 0.1 | H29: 0.9
A30: Inglesa | B30: 31 | C30: 1 | D30: A | E30: =IF(D30="F",0.6,IF(D30="C",0.3,IF(D30="D",0.4,IF(D30="E",0.5,IF(D30="A",0.1,IF(D30="G",0.7,IF(D30="H",0.8,IF(D30="B",0.2,"")))))))) -> 0.1 | H30: 0.9
A31: L sit | B31: 1 | C31: 2 | D31: A | E31: =IF(D31="F",0.6,IF(D31="C",0.3,IF(D31="D",0.4,IF(D31="E",0.5,IF(D31="A",0.1,IF(D31="G",0.7,IF(D31="H",0.8,IF(D31="B",0.2,"")))))))) -> 0.1 | H31: 0.85
A32: Kato 3" | B32: 26 | C32: 2 | D32: B | E32: =IF(D32="F",0.6,IF(D32="C",0.3,IF(D32="D",0.4,IF(D32="E",0.5,IF(D32="A",0.1,IF(D32="G",0.7,IF(D32="H",0.8,IF(D32="B",0.2,"")))))))) -> 0.2 | H32: 0.8
A33: Molino Sostenido | B33: 62 | C33: 1 | D33: C | E33: =IF(D33="F",0.6,IF(D33="C",0.3,IF(D33="D",0.4,IF(D33="E",0.5,IF(D33="A",0.1,IF(D33="G",0.7,IF(D33="H",0.8,IF(D33="B",0.2,"")))))))) -> 0.3 | F33: BPS | H33: 0.2
A34: Doble agrupado atras | B34: 32 | C34: 4 | D34: B | E34: =IF(D34="F",0.6,IF(D34="C",0.3,IF(D34="D",0.4,IF(D34="E",0.5,IF(D34="A",0.1,IF(D34="G",0.7,IF(D34="H",0.8,IF(D34="B",0.2,"")))))))) -> 0.2 | H34: 0.4
A36: SALTO DE CABALLO | C36: =A1 -> ISAAC | H36: ETAPA DE ELEMENTO
A37: NOMBRE | B37: NÚM DE ID | C37: GRUPO | D37: VALOR | E37: NOTA D | F37: SALTOS | G37: Probable NF
A38: Tsukahara en carpa | B38: 308 | C38: 3 | D38: 2 | F38: =10+D38 -> 12 | G38: =F38-1.3 -> 10.7 | H38: 0.5
A40: PARALELAS | E40: =A1 -> ISAAC | F40: NOTA D | G40: NP | H40: ETAPA DE ELEMENTO
A41: NOMBRE | B41: NÚM DE ID | C41: GRUPO | D41: VALOR | E41: Valor decimal | F41: =SUM(E42:E48) -> 1 | G41: =10+F41+F43+F49 -> 12.2
A42: Alemana | B42: 73 | C42: 3 | D42: A | E42: =IF(D42="F",0.6,IF(D42="C",0.3,IF(D42="D",0.4,IF(D42="E",0.5,IF(D42="A",0.1,IF(D42="G",0.7,IF(D42="H",0.8,IF(D42="B",0.2,"")))))))) -> 0.1 | F42: GRUPOS | G42: Probable NF | H42: 0.85
A43: L-sit | B43: 7 | C43: 2 | D43: A | E43: =IF(D43="F",0.6,IF(D43="C",0.3,IF(D43="D",0.4,IF(D43="E",0.5,IF(D43="A",0.1,IF(D43="G",0.7,IF(D43="H",0.8,IF(D43="B",0.2,"")))))))) -> 0.1 | F43: 1.2 | G43: =G41-1.5 -> 10.7 | H43: 0.85
A44: Kato | B44: 8 | C44: 2 | D44: B | E44: =IF(D44="F",0.6,IF(D44="C",0.3,IF(D44="D",0.4,IF(D44="E",0.5,IF(D44="A",0.1,IF(D44="G",0.7,IF(D44="H",0.8,IF(D44="B",0.2,"")))))))) -> 0.2 | H44: 0.7
...

Sheet CHAMPI
A1: CHAMPI | C1: N 9 | D1: AA NP | E1: =G3+G14+G25+G38+G43+G54 -> 70 | F1: AA | G1: =G5+G16+G27+G38+G43+G54 -> 65.5 | H1: =(H4+H5+H6+H7+H8+H9+H10+H11+H16+H17+H18+H19+H20+H21+H22+H15+H27+H28+H29+H30+H31+H32+H33+H26+H42+H38+H45+H46+H47+H48+H49+H53+H43+H44+H56+H57+H58+H59+H60+H54+H55)/41 -> 0.72463415
A2: PISO | E2: =A1 -> CHAMPI | F2: NOTA D | G2: NP | H2: ETAPA DE ELEMENTO
A3: NOMBRE | B3: NÚM DE ID | C3: GRUPO | D3: VALOR | E3: Valor decimal | F3: =SUM(E4:E11) -> 1.8 | G3: =10+F3+F5+F11 -> 13.4
A4: Doble en c atrás | B4: 3 | C4: 3 | D4: C | E4: =IF(D4="F",0.6,IF(D4="C",0.3,IF(D4="D",0.4,IF(D4="E",0.5,IF(D4="A",0.1,IF(D4="G",0.7,IF(D4="H",0.8,IF(D4="B",0.2,"")))))))) -> 0.3 | F4: GRUPOS | G4: Probable NF | H4: 0.3
A5: Doble giro y medio atras | B5: 10 | C5: 4 | D5: D | E5: =IF(D5="F",0.6,IF(D5="C",0.3,IF(D5="D",0.4,IF(D5="E",0.5,IF(D5="A",0.1,IF(D5="G",0.7,IF(D5="H",0.8,IF(D5="B",0.2,"")))))))) -> 0.4 | F5: 1.6 | G5: =G3-1.5 -> 11.9 | H5: 0.8
A6: Varani | B6: 14 | C6: 2 | D6: B | E6: =IF(D6="F",0.6,IF(D6="C",0.3,IF(D6="D",0.4,IF(D6="E",0.5,IF(D6="A",0.1,IF(D6="G",0.7,IF(D6="H",0.8,IF(D6="B",0.2,"")))))))) -> 0.2 | H6: 0.7
A7: Rusa 2" | B7: 2 | C7: 1 | D7: B | E7: =IF(D7="F",0.6,IF(D7="C",0.3,IF(D7="D",0.4,IF(D7="E",0.5,IF(D7="A",0.1,IF(D7="G",0.7,IF(D7="H",0.8,IF(D7="B",0.2,"")))))))) -> 0.2 | H7: 0.85
A8: Arabesca | B8: 61 | C8: 1 | D8: A | E8: =IF(D8="F",0.6,IF(D8="C",0.3,IF(D8="D",0.4,IF(D8="E",0.5,IF(D8="A",0.1,IF(D8="G",0.7,IF(D8="H",0.8,IF(D8="B",0.2,"")))))))) -> 0.1 | H8: 0.85
A9: Doble giro atras | B9: 9 | C9: 4 | D9: C | E9: =IF(D9="F",0.6,IF(D9="C",0.3,IF(D9="D",0.4,IF(D9="E",0.5,IF(D9="A",0.1,IF(D9="G",0.7,IF(D9="H",0.8,IF(D9="B",0.2,"")))))))) -> 0.3 | H9: 0.9
A10: Flick Flack | B10: 13 | C10: 3 | D10: A | E10: =IF(D10="F",0.6,IF(D10="C",0.3,IF(D10="D",0.4,IF(D10="E",0.5,IF(D10="A",0.1,IF(D10="G",0.7,IF(D10="H",0.8,IF(D10="B",0.2,"")))))))) -> 0.1 | F10: BPS | H10: 0.9
A11: Mortal Ext atrás | B11: 2 | C11: 3 | D11: B | E11: =IF(D11="F",0.6,IF(D11="C",0.3,IF(D11="D",0.4,IF(D11="E",0.5,IF(D11="A",0.1,IF(D11="G",0.7,IF(D11="H",0.8,IF(D11="B",0.2,"")))))))) -> 0.2 | H11: 0.9
A13: ARZONES | E13: =A1 -> CHAMPI | F13: NOTA D | G13: NP | H13: ETAPA DE ELEMENTO
A14: NOMBRE | B14: NÚM DE ID | C14: GRUPO | D14: VALOR | E14: Valor decimal | F14: =SUM(E15:E22) -> 0.6 | G14: =10+F14+F16+F22 -> 11.8
A15: Corte tijera | B15: 1 | C15: 1 | D15: A | E15: =IF(D15="F",0.6,IF(D15="C",0.3,IF(D15="D",0.4,IF(D15="E",0.5,IF(D15="A",0.1,IF(D15="G",0.7,IF(D15="H",0.8,IF(D15="B",0.2,"")))))))) -> 0.1 | F15: GRUPOS | G15: Probable NF | H15: 0.5
A16: Molino en arzones | B16: 1 | C16: 2 | D16: A | E16: =IF(D16="F",0.6,IF(D16="C",0.3,IF(D16="D",0.4,IF(D16="E",0.5,IF(D16="A",0.1,IF(D16="G",0.7,IF(D16="H",0.8,IF(D16="B",0.2,"")))))))) -> 0.1 | F16: 1.2 | G16: =G14-1.5 -> 10.3 | H16: 0.7
A17: Bajada lateral | B17: 1 | C17: 3 | D17: A | E17: =IF(D17="F",0.6,IF(D17="C",0.3,IF(D17="D",0.4,IF(D17="E",0.5,IF(D17="A",0.1,IF(D17="G",0.7,IF(D17="H",0.8,IF(D17="B",0.2,"")))))))) -> 0.1 | H17: 0.65
A18: Molino | B18: 7 | C18: 2 | D18: A | E18: =IF(D18="F",0.6,IF(D18="C",0.3,IF(D18="D",0.4,IF(D18="E",0.5,IF(D18="A",0.1,IF(D18="G",0.7,IF(D18="H",0.8,IF(D18="B",0.2,"")))))))) -> 0.1 | H18: 0.5
A19: 1/4 Splindle | B19: 25 | C19: 2 | D19: A | E19: =IF(D19="F",0.6,IF(D19="C",0.3,IF(D19="D",0.4,IF(D19="E",0.5,IF(D19="A",0.1,IF(D19="G",0.7,IF(D19="H",0.8,IF(D19="B",0.2,"")))))))) -> 0.1 | H19: 0.9
A20: Finlandesa | B20: 1 | C20: 4 | D20: A | E20: =IF(D20="F",0.6,IF(D20="C",0.3,IF(D20="D",0.4,IF(D20="E",0.5,IF(D20="A",0.1,IF(D20="G",0.7,IF(D20="H",0.8,IF(D20="B",0.2,"")))))))) -> 0.1 | H20: 0.2
F21: BPS | H21: 0.8
H22: 0.8
A24: ANILLOS | E24: =A1 -> CHAMPI | F24: NOTA D | G24: NP | H24: ETAPA DE ELEMENTO
A25: NOMBRE | B25: NÚM DE ID | C25: GRUPO | D25: VALOR | E25: Valor decimal | F25: =SUM(E26:E34) -> 0.8 | G25: =10+F25+F27+F33 -> 12.1
A26: Disloque | B26: 43 | C26: 1 | D26: A | E26: =IF(D26="F",0.6,IF(D26="C",0.3,IF(D26="D",0.4,IF(D26="E",0.5,IF(D26="A",0.1,IF(D26="G",0.7,IF(D26="H",0.8,IF(D26="B",0.2,"")))))))) -> 0.1 | F26: GRUPOS | G26: Probable NF | H26: 0.2
A27: Kip | B27: 8 | C27: 3 | D27: B | E27: =IF(D27="F",0.6,IF(D27="C",0.3,IF(D27="D",0.4,IF(D27="E",0.5,IF(D27="A",0.1,IF(D27="G",0.7,IF(D27="H",0.8,IF(D27="B",0.2,"")))))))) -> 0.2 | F27: 1.3 | G27: =G25-1.5 -> 10.6 | H27: 0.9
A28: kato 3" | B28: 26 | C28: 2 | D28: B | E28: =IF(D28="F",0.6,IF(D28="C",0.3,IF(D28="D",0.4,IF(D28="E",0.5,IF(D28="A",0.1,IF(D28="G",0.7,IF(D28="H",0.8,IF(D28="B",0.2,"")))))))) -> 0.2 | H28: 0.85
A29: Inlocada | B29: 37 | C29: 1 | D29: A | E29: =IF(D29="F",0.6,IF(D29="C",0.3,IF(D29="D",0.4,IF(D29="E",0.5,IF(D29="A",0.1,IF(D29="G",0.7,IF(D29="H",0.8,IF(D29="B",0.2,"")))))))) -> 0.1 | H29: 0.85
A30: Inglesa | B30: 31 | C30: 1 | D30: A | E30: =IF(D30="F",0.6,IF(D30="C",0.3,IF(D30="D",0.4,IF(D30="E",0.5,IF(D30="A",0.1,IF(D30="G",0.7,IF(D30="H",0.8,IF(D30="B",0.2,"")))))))) -> 0.1 | H30: 0.9
A31: L sit | B31: 1 | C31: 2 | D31: A | E31: =IF(D31="F",0.6,IF(D31="C",0.3,IF(D31="D",0.4,IF(D31="E",0.5,IF(D31="A",0.1,IF(D31="G",0.7,IF(D31="H",0.8,IF(D31="B",0.2,"")))))))) -> 0.1 | H31: 0.75
A32: Dislocada | B32: 25 | C32: 1 | D32: A | E32: =IF(D32="F",0.6,IF(D32="C",0.3,IF(D32="D",0.4,IF(D32="E",0.5,IF(D32="A",0.1,IF(D32="G",0.7,IF(D32="H",0.8,IF(D32="B",0.2,"")))))))) -> 0.1 | H32: 0.2
A33: Doble agrupado atras | B33: 32 | C33: 4 | D33: B | E33: =IF(D33="F",0.6,IF(D33="C",0.3,IF(D33="D",0.4,IF(D33="E",0.5,IF(D33="A",0.1,IF(D33="G",0.7,IF(D33="H",0.8,IF(D33="B",0.2,"")))))))) -> 0.2 | H33: 0.85
E34: -0.3 | F34: No impulso a manos
A36: SALTO DE CABALLO | C36: =A1 -> CHAMPI | H36: ETAPA DE ELEMENTO
A37: NOMBRE | B37: NÚM DE ID | C37: GRUPO | D37: VALOR | E37: NOTA D | F37: SALTOS | G37: Probable NF
A38: Tsukahara en C | B38: 307 | C38: 3 | D38: 1.8 | F38: =10+D38 -> 11.8 | G38: =F38-1.3 -> 10.5 | H38: 0.01
A40: PARALELAS | E40: =A1 -> CHAMPI | F40: NOTA D | G40: NP | H40: ETAPA DE ELEMENTO
A41: NOMBRE | B41: NÚM DE ID | C41: GRUPO | D41: VALOR | E41: Valor decimal | F41: =SUM(E42:E49) -> 1 | G41: =10+F41+F43+F49 -> 12.2
A42: Braq Subida de pecho | B42: 1 | C42: 1 | D42: A | E42: =IF(D42="F",0.6,IF(D42="C",0.3,IF(D42="D",0.4,IF(D42="E",0.5,IF(D42="A",0.1,IF(D42="G",0.7,IF(D42="H",0.8,IF(D42="B",0.2,"")))))))) -> 0.1 | F42: GRUPOS | G42: Probable NF | H42: 0.85
A43: Vuelo | B43: 1 | C43: 2 | D43: A | E43: =IF(D43="F",0.6,IF(D43="C",0.3,IF(D43="D",0.4,IF(D43="E",0.5,IF(D43="A",0.1,IF(D43="G",0.7,IF(D43="H",0.8,IF(D43="B",0.2,"")))))))) -> 0.1 | F43: 1.2 | G43: =G41-1.5 -> 10.7 | H43: 0.85
A44: Cambio | B44: 91 | C44: 2 | D44: A | E44: =IF(D44="F",0.6,IF(D44="C",0.3,IF(D44="D",0.4,IF(D44="E",0.5,IF(D44="A",0.1,IF(D44="G",0.7,IF(D44="H",0.8,IF(D44="B",0.2,"")))))))) -> 0.1 | H44: 0.9
...

Sheet MIKEL
A1: MIKEL | C1: N 9 | D1: AA NP | E1: =G3+G14+G25+F37+G40+G51 -> 75.4 | F1: AA | G1: =G5+G16+G27+G37+G42+G53 -> 66.6 | H1: =(H4+H5+H6+H7+H8+H9+H10+H11+H16+H17+H18+H19+H20+H21+H22+H15+H27+H28+H29+H30+H31+H32+H33+H26+H41+H37+H44+H45+H46+H47+H48+H52+H42+H43+H55+H56+H57+H58+H59+H53+H54)/41 -> 0.7695122
A2: PISO | C2: =A1 -> MIKEL | F2: NOTA D | G2: NP | H2: ETAPA DE ELEMENTO
A3: NOMBRE | B3: NÚM DE ID | C3: GRUPO | D3: VALOR | E3: Valor decimal | F3: =SUM(E4:E12)+F11 -> 1.4 | G3: =10+F3+F5+F11 -> 12.8
A4: Doble en c atrás | B4: 3 | C4: 3 | D4: C | E4: =IF(D4="F",0.6,IF(D4="C",0.3,IF(D4="D",0.4,IF(D4="E",0.5,IF(D4="A",0.1,IF(D4="G",0.7,IF(D4="H",0.8,IF(D4="B",0.2,"")))))))) -> 0.3 | F4: GRUPOS | G4: Probable NF | H4: 0.5
A5: Giro al frente | B5: 3 | C5: 4 | D5: C | E5: =IF(D5="F",0.6,IF(D5="C",0.3,IF(D5="D",0.4,IF(D5="E",0.5,IF(D5="A",0.1,IF(D5="G",0.7,IF(D5="H",0.8,IF(D5="B",0.2,"")))))))) -> 0.3 | F5: 1.4 | G5: =G3-1.5 -> 11.3 | H5: 0.6
A6: Carpado al frente | B6: 13 | C6: 2 | D6: A | E6: =IF(D6="F",0.6,IF(D6="C",0.3,IF(D6="D",0.4,IF(D6="E",0.5,IF(D6="A",0.1,IF(D6="G",0.7,IF(D6="H",0.8,IF(D6="B",0.2,"")))))))) -> 0.1 | H6: 0.85
A7: Circulo en suelo | B7: 79 | C7: 1 | D7: A | E7: =IF(D7="F",0.6,IF(D7="C",0.3,IF(D7="D",0.4,IF(D7="E",0.5,IF(D7="A",0.1,IF(D7="G",0.7,IF(D7="H",0.8,IF(D7="B",0.2,"")))))))) -> 0.1 | H7: 0.8
A8: Flick Flack | B8: 13 | C8: 3 | D8: A | E8: =IF(D8="F",0.6,IF(D8="C",0.3,IF(D8="D",0.4,IF(D8="E",0.5,IF(D8="A",0.1,IF(D8="G",0.7,IF(D8="H",0.8,IF(D8="B",0.2,"")))))))) -> 0.1 | H8: 0.85
A9: Giro atrás | B9: 9 | C9: 4 | D9: B | E9: =IF(D9="F",0.6,IF(D9="C",0.3,IF(D9="D",0.4,IF(D9="E",0.5,IF(D9="A",0.1,IF(D9="G",0.7,IF(D9="H",0.8,IF(D9="B",0.2,"")))))))) -> 0.2 | H9: 0.95
A10: Arabesca | B10: 61 | C10: 1 | D10: A | E10: =IF(D10="F",0.6,IF(D10="C",0.3,IF(D10="D",0.4,IF(D10="E",0.5,IF(D10="A",0.1,IF(D10="G",0.7,IF(D10="H",0.8,IF(D10="B",0.2,"")))))))) -> 0.1 | F10: BPP | H10: 0.95
A11: Mortal Ext atrás | B11: 2 | C11: 3 | D11: B | E11: =IF(D11="F",0.6,IF(D11="C",0.3,IF(D11="D",0.4,IF(D11="E",0.5,IF(D11="A",0.1,IF(D11="G",0.7,IF(D11="H",0.8,IF(D11="B",0.2,"")))))))) -> 0.2 | H11: 0.9
A13: ARZONES | C13: =A1 -> MIKEL | F13: NOTA D | G13: NP | H13: ETAPA DE ELEMENTO
A14: NOMBRE | B14: NÚM DE ID | C14: GRUPO | D14: VALOR | E14: Valor decimal | F14: =SUM(E15:E22) -> 1 | G14: =10+F14+F16+F22 -> 12.2
A15: Corte tijera | B15: 1 | C15: 1 | D15: A | E15: =IF(D15="F",0.6,IF(D15="C",0.3,IF(D15="D",0.4,IF(D15="E",0.5,IF(D15="A",0.1,IF(D15="G",0.7,IF(D15="H",0.8,IF(D15="B",0.2,"")))))))) -> 0.1 | F15: GRUPOS | G15: Probable NF | H15: 0.8
A16: Molino en arzones | B16: 1 | C16: 2 | D16: A | E16: =IF(D16="F",0.6,IF(D16="C",0.3,IF(D16="D",0.4,IF(D16="E",0.5,IF(D16="A",0.1,IF(D16="G",0.7,IF(D16="H",0.8,IF(D16="B",0.2,"")))))))) -> 0.1 | F16: 1.2 | G16: =G14-1.5 -> 10.7 | H16: 0.85
A17: 1/2 Recorrido lateral | B17: 38 | C17: 3 | D17: B | E17: =IF(D17="F",0.6,IF(D17="C",0.3,IF(D17="D",0.4,IF(D17="E",0.5,IF(D17="A",0.1,IF(D17="G",0.7,IF(D17="H",0.8,IF(D17="B",0.2,"")))))))) -> 0.2 | H17: 0.65
A18: Molino transversal | B18: 13 | C18: 2 | D18: A | E18: =IF(D18="F",0.6,IF(D18="C",0.3,IF(D18="D",0.4,IF(D18="E",0.5,IF(D18="A",0.1,IF(D18="G",0.7,IF(D18="H",0.8,IF(D18="B",0.2,"")))))))) -> 0.1 | H18: 0.6
A19: 1/2 Splindle | B19: 26 | C19: 2 | D19: B | E19: =IF(D19="F",0.6,IF(D19="C",0.3,IF(D19="D",0.4,IF(D19="E",0.5,IF(D19="A",0.1,IF(D19="G",0.7,IF(D19="H",0.8,IF(D19="B",0.2,"")))))))) -> 0.2 | H19: 0.85
A20: Molino | B20: 7 | C20: 2 | D20: A | E20: =IF(D20="F",0.6,IF(D20="C",0.3,IF(D20="D",0.4,IF(D20="E",0.5,IF(D20="A",0.1,IF(D20="G",0.7,IF(D20="H",0.8,IF(D20="B",0.2,"")))))))) -> 0.1 | H20: 0.5
A21: 1/4 Splindle | B21: 25 | C21: 2 | D21: A | E21: =IF(D21="F",0.6,IF(D21="C",0.3,IF(D21="D",0.4,IF(D21="E",0.5,IF(D21="A",0.1,IF(D21="G",0.7,IF(D21="H",0.8,IF(D21="B",0.2,"")))))))) -> 0.1 | F21: BPS | H21: 0.95
A22: Finlandesa | B22: 1 | C22: 4 | D22: A | E22: =IF(D22="F",0.6,IF(D22="C",0.3,IF(D22="D",0.4,IF(D22="E",0.5,IF(D22="A",0.1,IF(D22="G",0.7,IF(D22="H",0.8,IF(D22="B",0.2,"")))))))) -> 0.1 | H22: 0.9
A24: ANILLOS | C24: =A1 -> MIKEL | F24: NOTA D | G24: NP | H24: ETAPA DE ELEMENTO
A25: NOMBRE | B25: NÚM DE ID | C25: GRUPO | D25: VALOR | E25: Valor decimal | F25: =SUM(E26:E33) -> 1.5 | G25: =10+F25+F27+F33 -> 12.8
A26: Kip | B26: 8 | C26: 3 | D26: B | E26: =IF(D26="F",0.6,IF(D26="C",0.3,IF(D26="D",0.4,IF(D26="E",0.5,IF(D26="A",0.1,IF(D26="G",0.7,IF(D26="H",0.8,IF(D26="B",0.2,"")))))))) -> 0.2 | F26: GRUPOS | G26: Probable NF | H26: 0.65
A27: Cristo | B27: 68 | C27: 2 | D27: C | E27: =IF(D27="F",0.6,IF(D27="C",0.3,IF(D27="D",0.4,IF(D27="E",0.5,IF(D27="A",0.1,IF(D27="G",0.7,IF(D27="H",0.8,IF(D27="B",0.2,"")))))))) -> 0.3 | F27: 1.3 | G27: =G25-1.5 -> 11.3 | H27: 0.95
A28: Plancha dorsal | B28: 7 | C28: 2 | D28: A | E28: =IF(D28="F",0.6,IF(D28="C",0.3,IF(D28="D",0.4,IF(D28="E",0.5,IF(D28="A",0.1,IF(D28="G",0.7,IF(D28="H",0.8,IF(D28="B",0.2,"")))))))) -> 0.1 | H28: 0.95
A29: Inglesa | B29: 31 | C29: 1 | D29: A | E29: =IF(D29="F",0.6,IF(D29="C",0.3,IF(D29="D",0.4,IF(D29="E",0.5,IF(D29="A",0.1,IF(D29="G",0.7,IF(D29="H",0.8,IF(D29="B",0.2,"")))))))) -> 0.1 | H29: 0.85
A30: L sit | B30: 1 | C30: 2 | D30: A | E30: =IF(D30="F",0.6,IF(D30="C",0.3,IF(D30="D",0.4,IF(D30="E",0.5,IF(D30="A",0.1,IF(D30="G",0.7,IF(D30="H",0.8,IF(D30="B",0.2,"")))))))) -> 0.1 | H30: 0.85
A31: Kato 3" | B31: 26 | C31: 2 | D31: B | E31: =IF(D31="F",0.6,IF(D31="C",0.3,IF(D31="D",0.4,IF(D31="E",0.5,IF(D31="A",0.1,IF(D31="G",0.7,IF(D31="H",0.8,IF(D31="B",0.2,"")))))))) -> 0.2 | H31: 0.9
A32: Molino 3" | B32: 62 | C32: 1 | D32: C | E32: =IF(D32="F",0.6,IF(D32="C",0.3,IF(D32="D",0.4,IF(D32="E",0.5,IF(D32="A",0.1,IF(D32="G",0.7,IF(D32="H",0.8,IF(D32="B",0.2,"")))))))) -> 0.3 | F32: BPS | H32: 0.65
A33: Doble atras en c | B33: 32 | C33: 4 | D33: B | E33: =IF(D33="F",0.6,IF(D33="C",0.3,IF(D33="D",0.4,IF(D33="E",0.5,IF(D33="A",0.1,IF(D33="G",0.7,IF(D33="H",0.8,IF(D33="B",0.2,"")))))))) -> 0.2 | H33: 0.6
A35: SALTO DE CABALLO | C35: =A1 -> MIKEL | H35: ETAPA DE ELEMENTO
A36: NOMBRE | B36: NÚM DE ID | C36: GRUPO | D36: VALOR | E36: NOTA D | F36: SALTOS | G36: Probable NF
A37: Tsukahara ext | B37: 313 | C37: 3 | D37: 2.8 | F37: =10+D37 -> 12.8 | G37: =F37-1.3 -> 11.5 | H37: 0.8
A39: PARALELAS | C39: =A1 -> MIKEL | F39: NOTA D | G39: NP | H39: ETAPA DE ELEMENTO
A40: NOMBRE | B40: NÚM DE ID | C40: GRUPO | D40: VALOR | E40: Valor decimal | F40: =SUM(E41:E47) -> 1.1 | G40: =10+F40+F42+F48 -> 12.3
A41: Alemana | B41: 73 | C41: 3 | D41: A | E41: =IF(D41="F",0.6,IF(D41="C",0.3,IF(D41="D",0.4,IF(D41="E",0.5,IF(D41="A",0.1,IF(D41="G",0.7,IF(D41="H",0.8,IF(D41="B",0.2,"")))))))) -> 0.1 | F41: GRUPOS | G41: Probable NF | H41: 0.85
A42: L-sit | B42: 7 | C42: 2 | D42: A | E42: =IF(D42="F",0.6,IF(D42="C",0.3,IF(D42="D",0.4,IF(D42="E",0.5,IF(D42="A",0.1,IF(D42="G",0.7,IF(D42="H",0.8,IF(D42="B",0.2,"")))))))) -> 0.1 | F42: 1.2 | G42: =G40-1.5 -> 10.8 | H42: 0.5
A43: Kato | B43: 8 | C43: 2 | D43: B | E43: =IF(D43="F",0.6,IF(D43="C",0.3,IF(D43="D",0.4,IF(D43="E",0.5,IF(D43="A",0.1,IF(D43="G",0.7,IF(D43="H",0.8,IF(D43="B",0.2,"")))))))) -> 0.2 | H43: 0.5
A44: Moy extendido | B44: 15 | C44: 3 | D44: C | E44: =IF(D44="F",0.6,IF(D44="C",0.3,IF(D44="D",0.4,IF(D44="E",0.5,IF(D44="A",0.1,IF(D44="G",0.7,IF(D44="H",0.8,IF(D44="B",0.2,"")))))))) -> 0.3 | H44: 0.75
...

Sheet ALONSO
A1: ALONSO | C1: N 10 | D1: AA NP | E1: =G3+G15+G26+F39+G42+G53 -> 78.6 | F1: AA | G1: =G5+G17+G28+G39+G44+G55 -> 69.8 | H1: =(H4+H5+H6+H7+H8+H9+H10+H11+H16+H17+H18+H19+H20+H21+H22+H23+H27+H28+H29+H30+H31+H32+H33+H34+H39+H38+H44+H45+H46+H47+H48+H49+H50+H43+H55+H56+H57+H58+H59+H60+H61+H54)/42 -> 0.74904762
A2: PISO | C2: =A1 -> ALONSO | F2: NOTA D | G2: NP | H2: ETAPA DE ELEMENTO
A3: NOMBRE | B3: NÚM DE ID | C3: GRUPO | D3: VALOR | E3: Valor decimal | F3: =SUM(E4:E12) -> 2.3 | G3: =10+F3+F5+F11 -> 14.3
A4: Doble adelante en c | B4: 16 | C4: 2 | D4: D | E4: =IF(D4="F",0.6,IF(D4="C",0.3,IF(D4="D",0.4,IF(D4="E",0.5,IF(D4="A",0.1,IF(D4="G",0.7,IF(D4="H",0.8,IF(D4="B",0.2,"")))))))) -> 0.4 | F4: GRUPOS | G4: Probable NF | H4: 0.85
A5: Tsukahara | B5: 4 | C5: 3 | D5: D | E5: =IF(D5="F",0.6,IF(D5="C",0.3,IF(D5="D",0.4,IF(D5="E",0.5,IF(D5="A",0.1,IF(D5="G",0.7,IF(D5="H",0.8,IF(D5="B",0.2,"")))))))) -> 0.4 | F5: 2 | G5: =G3-1.5 -> 12.8 | H5: 0.9
A6: Doble giro atras | B6: 9 | C6: 4 | D6: C | E6: =IF(D6="F",0.6,IF(D6="C",0.3,IF(D6="D",0.4,IF(D6="E",0.5,IF(D6="A",0.1,IF(D6="G",0.7,IF(D6="H",0.8,IF(D6="B",0.2,"")))))))) -> 0.3 | H6: 0.65
A7: Flic facial | B7: 67 | C7: 1 | D7: A | E7: =IF(D7="F",0.6,IF(D7="C",0.3,IF(D7="D",0.4,IF(D7="E",0.5,IF(D7="A",0.1,IF(D7="G",0.7,IF(D7="H",0.8,IF(D7="B",0.2,"")))))))) -> 0.1 | H7: 0.85
A8: Doble en V atrás | B8: 16 | C8: 3 | D8: D | E8: =IF(D8="F",0.6,IF(D8="C",0.3,IF(D8="D",0.4,IF(D8="E",0.5,IF(D8="A",0.1,IF(D8="G",0.7,IF(D8="H",0.8,IF(D8="B",0.2,"")))))))) -> 0.4 | H8: 0.85
A9: Mortal Ext atrás | B9: 2 | C9: 3 | D9: B | E9: =IF(D9="F",0.6,IF(D9="C",0.3,IF(D9="D",0.4,IF(D9="E",0.5,IF(D9="A",0.1,IF(D9="G",0.7,IF(D9="H",0.8,IF(D9="B",0.2,"")))))))) -> 0.2 | H9: 0.85
A10: Salto del tigre | B10: 7 | C10: 2 | D10: A | E10: =IF(D10="F",0.6,IF(D10="C",0.3,IF(D10="D",0.4,IF(D10="E",0.5,IF(D10="A",0.1,IF(D10="G",0.7,IF(D10="H",0.8,IF(D10="B",0.2,"")))))))) -> 0.1 | F10: BPP | H10: 0.9
A11: Doble giro y medio atras | B11: 10 | C11: 4 | D11: D | E11: =IF(D11="F",0.6,IF(D11="C",0.3,IF(D11="D",0.4,IF(D11="E",0.5,IF(D11="A",0.1,IF(D11="G",0.7,IF(D11="H",0.8,IF(D11="B",0.2,"")))))))) -> 0.4 | H11: 0.9
D12: BPC
A14: ARZONES | C14: =A1 -> ALONSO | F14: NOTA D | G14: NP | H14: ETAPA DE ELEMENTO
A15: NOMBRE | B15: NÚM DE ID | C15: GRUPO | D15: VALOR | E15: Valor decimal | F15: =SUM(E16:E21) -> 0.6 | G15: =10+F15+F17+F23 -> 11.8
A16: Corte tijera | B16: 1 | C16: 1 | D16: A | E16: =IF(D16="F",0.6,IF(D16="C",0.3,IF(D16="D",0.4,IF(D16="E",0.5,IF(D16="A",0.1,IF(D16="G",0.7,IF(D16="H",0.8,IF(D16="B",0.2,"")))))))) -> 0.1 | F16: GRUPOS | G16: Probable NF | H16: 0.8
A17: Molino en arzones | B17: 1 | C17: 2 | D17: A | E17: =IF(D17="F",0.6,IF(D17="C",0.3,IF(D17="D",0.4,IF(D17="E",0.5,IF(D17="A",0.1,IF(D17="G",0.7,IF(D17="H",0.8,IF(D17="B",0.2,"")))))))) -> 0.1 | F17: 1.2 | G17: =G15-1.5 -> 10.3 | H17: 0.7
A18: Bajada lateral | B18: 1 | C18: 3 | D18: A | E18: =IF(D18="F",0.6,IF(D18="C",0.3,IF(D18="D",0.4,IF(D18="E",0.5,IF(D18="A",0.1,IF(D18="G",0.7,IF(D18="H",0.8,IF(D18="B",0.2,"")))))))) -> 0.1 | H18: 0.65
A19: Molino | B19: 7 | C19: 2 | D19: A | E19: =IF(D19="F",0.6,IF(D19="C",0.3,IF(D19="D",0.4,IF(D19="E",0.5,IF(D19="A",0.1,IF(D19="G",0.7,IF(D19="H",0.8,IF(D19="B",0.2,"")))))))) -> 0.1 | H19: 0.6
A20: 1/4 Splindle | B20: 25 | C20: 2 | D20: A | E20: =IF(D20="F",0.6,IF(D20="C",0.3,IF(D20="D",0.4,IF(D20="E",0.5,IF(D20="A",0.1,IF(D20="G",0.7,IF(D20="H",0.8,IF(D20="B",0.2,"")))))))) -> 0.1
A21: Finlandesa | B21: 1 | C21: 4 | D21: A | E21: =IF(D21="F",0.6,IF(D21="C",0.3,IF(D21="D",0.4,IF(D21="E",0.5,IF(D21="A",0.1,IF(D21="G",0.7,IF(D21="H",0.8,IF(D21="B",0.2,"")))))))) -> 0.1
F22: BPP | H22: 0.8
H23: 0.8
A25: ANILLOS | C25: =A1 -> ALONSO | F25: NOTA D | G25: NP | H25: ETAPA DE ELEMENTO
A26: NOMBRE | B26: NÚM DE ID | C26: GRUPO | D26: VALOR | E26: Valor decimal | F26: =SUM(E27:E34) -> 1.5 | G26: =10+F26+F28+F34 -> 12.9
A27: Kip cristo | B27: 39 | C27: 3 | D27: C | E27: =IF(D27="F",0.6,IF(D27="C",0.3,IF(D27="D",0.4,IF(D27="E",0.5,IF(D27="A",0.1,IF(D27="G",0.7,IF(D27="H",0.8,IF(D27="B",0.2,"")))))))) -> 0.3 | F27: GRUPOS | G27: Probable NF | H27: 0.65
A28: Plancha dorsal | B28: 7 | C28: 2 | D28: A | E28: =IF(D28="F",0.6,IF(D28="C",0.3,IF(D28="D",0.4,IF(D28="E",0.5,IF(D28="A",0.1,IF(D28="G",0.7,IF(D28="H",0.8,IF(D28="B",0.2,"")))))))) -> 0.1 | F28: 1.4 | G28: =G26-1.5 -> 11.4 | H28: 0.9
A29: Inlocada | B29: 37 | C29: 1 | D29: A | E29: =IF(D29="F",0.6,IF(D29="C",0.3,IF(D29="D",0.4,IF(D29="E",0.5,IF(D29="A",0.1,IF(D29="G",0.7,IF(D29="H",0.8,IF(D29="B",0.2,"")))))))) -> 0.1 | H29: 0.9
A30: Inglesa | B30: 31 | C30: 1 | D30: A | E30: =IF(D30="F",0.6,IF(D30="C",0.3,IF(D30="D",0.4,IF(D30="E",0.5,IF(D30="A",0.1,IF(D30="G",0.7,IF(D30="H",0.8,IF(D30="B",0.2,"")))))))) -> 0.1 | H30: 0.95
A31: L sit | B31: 1 | C31: 2 | D31: A | E31: =IF(D31="F",0.6,IF(D31="C",0.3,IF(D31="D",0.4,IF(D31="E",0.5,IF(D31="A",0.1,IF(D31="G",0.7,IF(D31="H",0.8,IF(D31="B",0.2,"")))))))) -> 0.1 | H31: 0.9
A32: Kato 3" | B32: 26 | C32: 2 | D32: B | E32: =IF(D32="F",0.6,IF(D32="C",0.3,IF(D32="D",0.4,IF(D32="E",0.5,IF(D32="A",0.1,IF(D32="G",0.7,IF(D32="H",0.8,IF(D32="B",0.2,"")))))))) -> 0.2 | H32: 0.65
A33: Gigante Sostenido | B33: 75 | C33: 1 | D33: C | E33: =IF(D33="F",0.6,IF(D33="C",0.3,IF(D33="D",0.4,IF(D33="E",0.5,IF(D33="A",0.1,IF(D33="G",0.7,IF(D33="H",0.8,IF(D33="B",0.2,"")))))))) -> 0.3 | F33: BPP | H33: 0.75
A34: Doble extendido atras | B34: 33 | C34: 4 | D34: C | E34: =IF(D34="F",0.6,IF(D34="C",0.3,IF(D34="D",0.4,IF(D34="E",0.5,IF(D34="A",0.1,IF(D34="G",0.7,IF(D34="H",0.8,IF(D34="B",0.2,"")))))))) -> 0.3 | H34: 0.7
A36: SALTO DE CABALLO | C36: =A1 -> ALONSO | H36: ETAPA DE ELEMENTO
A37: NOMBRE | B37: NÚM DE ID | C37: GRUPO | D37: VALOR
A38: Tsukahara ext con 1 | B38: 125 | C38: 1 | D38: 3.6 | E38: NOTA D | F38: SALTOS | G38: Probable NF | H38: 0.65
A39: Tsukahara extendida | B39: 313 | C39: 3 | D39: 2.8 | F39: =10+D38 -> 13.6 | G39: =F39-1.3 -> 12.3 | H39: 0.7
A41: PARALELAS | C41: =A1 -> ALONSO | F41: NOTA D | G41: NP | H41: ETAPA DE ELEMENTO
A42: NOMBRE | B42: NÚM DE ID | C42: GRUPO | D42: VALOR | E42: Valor decimal | F42: =SUM(E43:E50) -> 1.6 | G42: =10+F42+F44+F50 -> 13
A43: Alemana | B43: 73 | C43: 3 | D43: A | E43: =IF(D43="F",0.6,IF(D43="C",0.3,IF(D43="D",0.4,IF(D43="E",0.5,IF(D43="A",0.1,IF(D43="G",0.7,IF(D43="H",0.8,IF(D43="B",0.2,"")))))))) -> 0.1 | F43: GRUPOS | G43: Probable NF | H43: 0.9
A44: Kato | B44: 8 | C44: 2 | D44: B | E44: =IF(D44="F",0.6,IF(D44="C",0.3,IF(D44="D",0.4,IF(D44="E",0.5,IF(D44="A",0.1,IF(D44="G",0.7,IF(D44="H",0.8,IF(D44="B",0.2,"")))))))) -> 0.2 | F44: 1.4 | G44: =G42-1.5 -> 11.5 | H44: 0.85
...

Sheet RICHIE
A1: RICHIE | C1: N 10 | D1: AA NP | E1: =G3+G14+G25+F39+G42+G53 -> 82.3 | F1: AA | G1: =G5+G16+G27+G39+G44+G55 -> 73.5 | H1: =(H4+H5+H6+H7+H9+H8+H10+H11+H16+H17+H18+H19+H20+H21+H22+H15+H27+H28+H29+H30+H31+H32+H33+H26+H39+H38+H44+H45+H46+H47+H48+H49+H50+H43+H55+H56+H57+H58+H59+H60+H61+H54)/42 -> 0.78571429
A2: PISO | C2: =A1 -> RICHIE | F2: NOTA D | G2: NP | H2: ETAPA DE ELEMENTO
A3: NOMBRE | B3: NÚM DE ID | C3: GRUPO | D3: VALOR | E3: Valor decimal | F3: =SUM(E4:E12) -> 2.4 | G3: =10+F3+F5+F11 -> 14.4
A4: Doble en V atrás | B4: 16 | C4: 3 | D4: D | E4: =IF(D4="F",0.6,IF(D4="C",0.3,IF(D4="D",0.4,IF(D4="E",0.5,IF(D4="A",0.1,IF(D4="G",0.7,IF(D4="H",0.8,IF(D4="B",0.2,"")))))))) -> 0.4 | F4: GRUPOS | G4: Probable NF | H4: 0.85
A5: Doble adelante en c | B5: 16 | C5: 2 | D5: D | E5: =IF(D5="F",0.6,IF(D5="C",0.3,IF(D5="D",0.4,IF(D5="E",0.5,IF(D5="A",0.1,IF(D5="G",0.7,IF(D5="H",0.8,IF(D5="B",0.2,"")))))))) -> 0.4 | F5: 2 | G5: =G3-1.5 -> 12.9 | H5: 0.8
A6: Doble giro atras | B6: 9 | C6: 4 | D6: C | E6: =IF(D6="F",0.6,IF(D6="C",0.3,IF(D6="D",0.4,IF(D6="E",0.5,IF(D6="A",0.1,IF(D6="G",0.7,IF(D6="H",0.8,IF(D6="B",0.2,"")))))))) -> 0.3 | H6: 0.9
A7: Fedorchenko | B7: 105 | C7: 1 | D7: C | E7: =IF(D7="F",0.6,IF(D7="C",0.3,IF(D7="D",0.4,IF(D7="E",0.5,IF(D7="A",0.1,IF(D7="G",0.7,IF(D7="H",0.8,IF(D7="B",0.2,"")))))))) -> 0.3 | H7: 0.9
A8: Split | B8: 55 | C8: 1 | D8: A | E8: =IF(D8="F",0.6,IF(D8="C",0.3,IF(D8="D",0.4,IF(D8="E",0.5,IF(D8="A",0.1,IF(D8="G",0.7,IF(D8="H",0.8,IF(D8="B",0.2,"")))))))) -> 0.1 | H8: 0.95
A9: Doble Giro al frente | B9: 4 | C9: 4 | D9: D | E9: =IF(D9="F",0.6,IF(D9="C",0.3,IF(D9="D",0.4,IF(D9="E",0.5,IF(D9="A",0.1,IF(D9="G",0.7,IF(D9="H",0.8,IF(D9="B",0.2,"")))))))) -> 0.4 | H9: 0.85
A10: Arabesca | B10: 61 | C10: 1 | D10: A | E10: =IF(D10="F",0.6,IF(D10="C",0.3,IF(D10="D",0.4,IF(D10="E",0.5,IF(D10="A",0.1,IF(D10="G",0.7,IF(D10="H",0.8,IF(D10="B",0.2,"")))))))) -> 0.1 | F10: BPP | H10: 0.9
A11: Triple giro atrás | B11: 22 | C11: 4 | D11: D | E11: =IF(D11="F",0.6,IF(D11="C",0.3,IF(D11="D",0.4,IF(D11="E",0.5,IF(D11="A",0.1,IF(D11="G",0.7,IF(D11="H",0.8,IF(D11="B",0.2,"")))))))) -> 0.4 | H11: 0.85
D12: BPC
A13: ARZONES | C13: =A1 -> RICHIE | F13: NOTA D | G13: NP | H13: ETAPA DE ELEMENTO
A14: NOMBRE | B14: NÚM DE ID | C14: GRUPO | D14: VALOR | E14: Valor decimal | F14: =SUM(E15:E23) -> 2.3 | G14: =10+F14+F16+F22 -> 14
A15: Corte tijera | B15: 1 | C15: 1 | D15: A | E15: =IF(D15="F",0.6,IF(D15="C",0.3,IF(D15="D",0.4,IF(D15="E",0.5,IF(D15="A",0.1,IF(D15="G",0.7,IF(D15="H",0.8,IF(D15="B",0.2,"")))))))) -> 0.1 | F15: GRUPOS | G15: Probable NF | H15: 0.85
A16: Cheka | B16: 74 | C16: 2 | D16: B | E16: =IF(D16="F",0.6,IF(D16="C",0.3,IF(D16="D",0.4,IF(D16="E",0.5,IF(D16="A",0.1,IF(D16="G",0.7,IF(D16="H",0.8,IF(D16="B",0.2,"")))))))) -> 0.2 | F16: 1.7 | G16: =G14-1.5 -> 12.5 | H16: 0.9
A17: Bajada 1/2 recorrido | B17: 38 | C17: 3 | D17: B | E17: =IF(D17="F",0.6,IF(D17="C",0.3,IF(D17="D",0.4,IF(D17="E",0.5,IF(D17="A",0.1,IF(D17="G",0.7,IF(D17="H",0.8,IF(D17="B",0.2,"")))))))) -> 0.2 | H17: 0.65
A18: Magyar en punta (splindle) | B18: 34 | C18: 2 | D18: D | E18: =IF(D18="F",0.6,IF(D18="C",0.3,IF(D18="D",0.4,IF(D18="E",0.5,IF(D18="A",0.1,IF(D18="G",0.7,IF(D18="H",0.8,IF(D18="B",0.2,"")))))))) -> 0.4 | H18: 0.9
A19: Tong Fei | B19: 58 | C19: 3 | D19: D | E19: =IF(D19="F",0.6,IF(D19="C",0.3,IF(D19="D",0.4,IF(D19="E",0.5,IF(D19="A",0.1,IF(D19="G",0.7,IF(D19="H",0.8,IF(D19="B",0.2,"")))))))) -> 0.4 | H19: 0.65
A20: Magyar | B20: 34 | C20: 3 | D20: D | E20: =IF(D20="F",0.6,IF(D20="C",0.3,IF(D20="D",0.4,IF(D20="E",0.5,IF(D20="A",0.1,IF(D20="G",0.7,IF(D20="H",0.8,IF(D20="B",0.2,"")))))))) -> 0.4 | H20: 0.85
A21: Sivado | B21: 40 | C21: 3 | D21: D | E21: =IF(D21="F",0.6,IF(D21="C",0.3,IF(D21="D",0.4,IF(D21="E",0.5,IF(D21="A",0.1,IF(D21="G",0.7,IF(D21="H",0.8,IF(D21="B",0.2,"")))))))) -> 0.4 | F21: BPP | H21: 0.8
A22: Circulo a manos PA | B22: 20 | C22: 4 | D22: B | E22: =IF(D22="F",0.6,IF(D22="C",0.3,IF(D22="D",0.4,IF(D22="E",0.5,IF(D22="A",0.1,IF(D22="G",0.7,IF(D22="H",0.8,IF(D22="B",0.2,"")))))))) -> 0.2 | H22: 0.65
A24: ANILLOS | C24: =A1 -> RICHIE | F24: NOTA D | G24: NP | H24: ETAPA DE ELEMENTO
A25: NOMBRE | B25: NÚM DE ID | C25: GRUPO | D25: VALOR | E25: Valor decimal | F25: =SUM(E26:E34)+F29 -> 2 | G25: =10+F25+F27+F33 -> 13.4
A26: Disloque | B26: 43 | C26: 1 | D26: A | E26: =IF(D26="F",0.6,IF(D26="C",0.3,IF(D26="D",0.4,IF(D26="E",0.5,IF(D26="A",0.1,IF(D26="G",0.7,IF(D26="H",0.8,IF(D26="B",0.2,"")))))))) -> 0.1 | F26: GRUPOS | G26: Probable NF | H26: 0.85
A27: Kip | B27: 8 | C27: 3 | D27: B | E27: =IF(D27="F",0.6,IF(D27="C",0.3,IF(D27="D",0.4,IF(D27="E",0.5,IF(D27="A",0.1,IF(D27="G",0.7,IF(D27="H",0.8,IF(D27="B",0.2,"")))))))) -> 0.2 | F27: 1.4 | G27: =G25-1.5 -> 11.9 | H27: 0.75
A28: Cristo | B28: 68 | C28: 2 | D28: C | E28: =IF(D28="F",0.6,IF(D28="C",0.3,IF(D28="D",0.4,IF(D28="E",0.5,IF(D28="A",0.1,IF(D28="G",0.7,IF(D28="H",0.8,IF(D28="B",0.2,"")))))))) -> 0.3 | H28: 0.6
A29: Inglesa | B29: 31 | C29: 1 | D29: A | E29: =IF(D29="F",0.6,IF(D29="C",0.3,IF(D29="D",0.4,IF(D29="E",0.5,IF(D29="A",0.1,IF(D29="G",0.7,IF(D29="H",0.8,IF(D29="B",0.2,"")))))))) -> 0.1 | H29: 0.6
A30: Jonasson | B30: 45 | C30: 1 | D30: C | E30: =IF(D30="F",0.6,IF(D30="C",0.3,IF(D30="D",0.4,IF(D30="E",0.5,IF(D30="A",0.1,IF(D30="G",0.7,IF(D30="H",0.8,IF(D30="B",0.2,"")))))))) -> 0.3 | H30: 0.75
A31: Molino | B31: 62 | C31: 1 | D31: C | E31: =IF(D31="F",0.6,IF(D31="C",0.3,IF(D31="D",0.4,IF(D31="E",0.5,IF(D31="A",0.1,IF(D31="G",0.7,IF(D31="H",0.8,IF(D31="B",0.2,"")))))))) -> 0.3 | H31: 0.65
A32: Gigante | B32: 75 | C32: 1 | D32: C | E32: =IF(D32="F",0.6,IF(D32="C",0.3,IF(D32="D",0.4,IF(D32="E",0.5,IF(D32="A",0.1,IF(D32="G",0.7,IF(D32="H",0.8,IF(D32="B",0.2,"")))))))) -> 0.3 | F32: BPP | H32: 0.85
A33: Multiple agrupado atras | B33: 52 | C33: 4 | D33: C | E33: =IF(D33="F",0.6,IF(D33="C",0.3,IF(D33="D",0.4,IF(D33="E",0.5,IF(D33="A",0.1,IF(D33="G",0.7,IF(D33="H",0.8,IF(D33="B",0.2,"")))))))) -> 0.3 | H33: 0.8
D34: BPC | E34: 0.1
A36: SALTO DE CABALLO | C36: =A1 -> RICHIE | H36: ETAPA DE ELEMENTO
A37: NOMBRE | B37: NÚM DE ID | C37: GRUPO | D37: VALOR
A38: Tsukahara ext con 1 giro | B38: 125 | C38: 1 | D38: 3.6 | E38: NOTA D | F38: SALTOS | G38: Probable NF | H38: 0.6
A39: Tsukahara extendida | B39: 313 | C39: 3 | D39: 2.8 | F39: =10+D38 -> 13.6 | G39: =F39-1.3 -> 12.3 | H39: 0.7
A41: PARALELAS | C41: =A1 -> RICHIE | F41: NOTA D | G41: NP | H41: ETAPA DE ELEMENTO
A42: NOMBRE | B42: NÚM DE ID | C42: GRUPO | D42: VALOR | E42: Valor decimal | F42: =SUM(E43:E50) -> 1.7 | G42: =10+F42+F44+F50 -> 13.2
A43: Felge | B43: 116 | C43: 3 | D43: B | E43: =IF(D43="F",0.6,IF(D43="C",0.3,IF(D43="D",0.4,IF(D43="E",0.5,IF(D43="A",0.1,IF(D43="G",0.7,IF(D43="H",0.8,IF(D43="B",0.2,"")))))))) -> 0.2 | F43: GRUPOS | G43: Probable NF | H43: 0.9
...

Sheet DIEGO J
A1: DIEGO | C1: N FIG | D1: AA NP | E1: =G3+G15+G26+F40+G43+G54 -> 87.8 | F1: AA | G1: =G5+G17+G28+G40+G45+G56 -> 79 | H1: =(H4+H5+H6+H7+H8+H9+H10+H11+H16+H17+H18+H19+H20+H21+H22+H23+H27+H28+H29+H30+H31+H32+H33+H34+H39+H40+H44+H45+H46+H47+H48+H49+H50+H51+H55+H56+H57+H58+H59+H60+H61+H62)/42 -> 0.80952381
A2: PISO | C2: =A1 -> DIEGO | F2: NOTA D | G2: NP | H2: ETAPA DE ELEMENTO
A3: NOMBRE | B3: NÚM DE ID | C3: GRUPO | D3: VALOR | E3: Valor decimal | F3: =SUM(E4:E12) -> 3 | G3: =10+F3+F5+F11 -> 15
A4: Doble doble | B4: 5 | C4: 3 | D4: E | E4: =IF(D4="F",0.6,IF(D4="C",0.3,IF(D4="D",0.4,IF(D4="E",0.5,IF(D4="A",0.1,IF(D4="G",0.7,IF(D4="H",0.8,IF(D4="B",0.2,"")))))))) -> 0.5 | F4: GRUPOS | G4: Probable NF | H4: 0.8
A5: Giro al frente | B5: 3 | C5: 4 | D5: C | E5: =IF(D5="F",0.6,IF(D5="C",0.3,IF(D5="D",0.4,IF(D5="E",0.5,IF(D5="A",0.1,IF(D5="G",0.7,IF(D5="H",0.8,IF(D5="B",0.2,"")))))))) -> 0.3 | F5: 2 | G5: =G3-1.5 -> 13.5 | H5: 0.85
A6: Doble adelante en c | B6: 16 | C6: 2 | D6: D | E6: =IF(D6="F",0.6,IF(D6="C",0.3,IF(D6="D",0.4,IF(D6="E",0.5,IF(D6="A",0.1,IF(D6="G",0.7,IF(D6="H",0.8,IF(D6="B",0.2,"")))))))) -> 0.4 | H6: 0.7
A7: Doble giro atras | B7: 9 | C7: 4 | D7: C | E7: =IF(D7="F",0.6,IF(D7="C",0.3,IF(D7="D",0.4,IF(D7="E",0.5,IF(D7="A",0.1,IF(D7="G",0.7,IF(D7="H",0.8,IF(D7="B",0.2,"")))))))) -> 0.3 | H7: 0.75
A8: Endo cerrado a manos | B8: 45 | C8: 1 | D8: C | E8: =IF(D8="F",0.6,IF(D8="C",0.3,IF(D8="D",0.4,IF(D8="E",0.5,IF(D8="A",0.1,IF(D8="G",0.7,IF(D8="H",0.8,IF(D8="B",0.2,"")))))))) -> 0.3 | H8: 0.9
A9: Fedorchenko | B9: 105 | C9: 1 | D9: C | E9: =IF(D9="F",0.6,IF(D9="C",0.3,IF(D9="D",0.4,IF(D9="E",0.5,IF(D9="A",0.1,IF(D9="G",0.7,IF(D9="H",0.8,IF(D9="B",0.2,"")))))))) -> 0.3 | H9: 0.85
A10: Triple giro atrás | B10: 22 | C10: 4 | D10: D | E10: =IF(D10="F",0.6,IF(D10="C",0.3,IF(D10="D",0.4,IF(D10="E",0.5,IF(D10="A",0.1,IF(D10="G",0.7,IF(D10="H",0.8,IF(D10="B",0.2,"")))))))) -> 0.4 | F10: BPP | H10: 0.9
A11: Tsukahara | B11: 4 | C11: 3 | D11: D | E11: =IF(D11="F",0.6,IF(D11="C",0.3,IF(D11="D",0.4,IF(D11="E",0.5,IF(D11="A",0.1,IF(D11="G",0.7,IF(D11="H",0.8,IF(D11="B",0.2,"")))))))) -> 0.4 | H11: 0.8
D12: BPC | E12: 0.1
A14: ARZONES | C14: =A1 -> DIEGO | F14: NOTA D | G14: NP | H14: ETAPA DE ELEMENTO
A15: NOMBRE | B15: NÚM DE ID | C15: GRUPO | D15: VALOR | E15: Valor decimal | F15: =SUM(E16:E24)+F19 -> 2.9 | G15: =10+F15+F17+F23 -> 14.9
